Workbook
Name CE_epoch1: Backprop_more_image!$AQ$27
Name CE_epoch2: Backprop_more_image!$AQ$55
Name CE_epoch3: Backprop_more_image!$AQ$83
Name CE_epoch4: Backprop_more_image!$AQ$113
Name Classes: 'Dataset-Tumor'!$CG$6:$CG$9
Name Samples: 'Dataset-Tumor'!$CH$6:$CH$9

Sheet Intro
A1: 201 | B1: 201 | C1: 201 | D1: 201 | E1: 201 | F1: 201 | G1: 201 | H1: 201 | I1: 201 | J1: 201 | K1: 201 | L1: 201 | M1: 200 | N1: 200 | O1: 202 | P1: 206 | Q1: 205 | R1: 204 | S1: 201 | T1: 200 | U1: 200 | V1: 200 | W1: 200 | X1: 200 | Y1: 200 | Z1: 200 | AA1: 200 | AB1: 200 | AC1: 200 | AD1: 200 | AE1: 200 | AF1: 200 | AG1: 157 | AH1: 176 | AI1: 153 | AJ1: 148 | AK1: 178 | AL1: 193 | AM1: 207 | AN1: 181 | AO1: 183 | AP1: 180 | AQ1: 182 | AR1: 155 | AS1: 132 | AT1: 173 | AU1: 193 | AV1: 182 | AW1: 161 | AX1: 164 | AY1: 188 | AZ1: 192 | BA1: 175 | BB1: 178 | BC1: 159 | BD1: 149 | BE1: 118 | BF1: 124 | BG1: 158 | BH1: 164 | BI1: 168 | BJ1: 203 | BK1: 197 | BL1: 170
A2: 201 | B2: 201 | C2: 201 | D2: 201 | E2: 201 | F2: 201 | G2: 201 | H2: 201 | I2: 201 | J2: 201 | K2: 201 | L2: 200 | M2: 199 | N2: 203 | O2: 190 | P2: 142 | Q2: 139 | R2: 169 | S2: 193 | T2: 203 | U2: 200 | V2: 200 | W2: 200 | X2: 200 | Y2: 200 | Z2: 200 | AA2: 200 | AB2: 200 | AC2: 200 | AD2: 200 | AE2: 200 | AF2: 200 | AG2: 158 | AH2: 144 | AI2: 130 | AJ2: 157 | AK2: 181 | AL2: 195 | AM2: 198 | AN2: 190 | AO2: 190 | AP2: 187 | AQ2: 188 | AR2: 184 | AS2: 163 | AT2: 174 | AU2: 200 | AV2: 192 | AW2: 171 | AX2: 168 | AY2: 187 | AZ2: 183 | BA2: 187 | BB2: 187 | BC2: 181 | BD2: 166 | BE2: 111 | BF2: 130 | BG2: 160 | BH2: 171 | BI2: 169 | BJ2: 188 | BK2: 193 | BL2: 191
A3: 201 | B3: 201 | C3: 201 | D3: 201 | E3: 201 | F3: 201 | G3: 201 | H3: 201 | I3: 201 | J3: 201 | K3: 201 | L3: 200 | M3: 194 | N3: 148 | O3: 64 | P3: 21 | Q3: 25 | R3: 49 | S3: 88 | T3: 184 | U3: 206 | V3: 200 | W3: 200 | X3: 200 | Y3: 200 | Z3: 200 | AA3: 200 | AB3: 200 | AC3: 200 | AD3: 200 | AE3: 200 | AF3: 200 | AG3: 144 | AH3: 124 | AI3: 164 | AJ3: 143 | AK3: 173 | AL3: 205 | AM3: 189 | AN3: 187 | AO3: 187 | AP3: 193 | AQ3: 196 | AR3: 196 | AS3: 189 | AT3: 193 | AU3: 196 | AV3: 198 | AW3: 185 | AX3: 178 | AY3: 187 | AZ3: 183 | BA3: 190 | BB3: 190 | BC3: 184 | BD3: 167 | BE3: 123 | BF3: 150 | BG3: 174 | BH3: 191 | BI3: 163 | BJ3: 169 | BK3: 184 | BL3: 196
A4: 201 | B4: 201 | C4: 201 | D4: 201 | E4: 201 | F4: 201 | G4: 201 | H4: 201 | I4: 201 | J4: 200 | K4: 163 | L4: 115 | M4: 101 | N4: 52 | O4: 26 | P4: 12 | Q4: 10 | R4: 14 | S4: 48 | T4: 76 | U4: 170 | V4: 206 | W4: 200 | X4: 200 | Y4: 200 | Z4: 201 | AA4: 201 | AB4: 200 | AC4: 200 | AD4: 200 | AE4: 200 | AF4: 200 | AG4: 113 | AH4: 172 | AI4: 175 | AJ4: 139 | AK4: 162 | AL4: 177 | AM4: 179 | AN4: 184 | AO4: 183 | AP4: 184 | AQ4: 188 | AR4: 193 | AS4: 196 | AT4: 202 | AU4: 201 | AV4: 195 | AW4: 172 | AX4: 148 | AY4: 175 | AZ4: 190 | BA4: 194 | BB4: 190 | BC4: 188 | BD4: 180 | BE4: 146 | BF4: 178 | BG4: 178 | BH4: 198 | BI4: 179 | BJ4: 178 | BK4: 184 | BL4: 181
A5: 201 | B5: 201 | C5: 201 | D5: 201 | E5: 201 | F5: 201 | G5: 201 | H5: 201 | I5: 203 | J5: 164 | K5: 76 | L5: 31 | M5: 17 | N5: 37 | O5: 44 | P5: 31 | Q5: 30 | R5: 8 | S5: 34 | T5: 24 | U5: 35 | V5: 147 | W5: 205 | X5: 200 | Y5: 201 | Z5: 201 | AA5: 201 | AB5: 201 | AC5: 200 | AD5: 200 | AE5: 200 | AF5: 200 | AG5: 159 | AH5: 182 | AI5: 185 | AJ5: 140 | AK5: 147 | AL5: 164 | AM5: 181 | AN5: 190 | AO5: 181 | AP5: 183 | AQ5: 185 | AR5: 194 | AS5: 206 | AT5: 211 | AU5: 205 | AV5: 189 | AW5: 169 | AX5: 113 | AY5: 175 | AZ5: 193 | BA5: 193 | BB5: 197 | BC5: 194 | BD5: 187 | BE5: 183 | BF5: 191 | BG5: 198 | BH5: 207 | BI5: 190 | BJ5: 196 | BK5: 204 | BL5: 200
A6: 201 | B6: 201 | C6: 201 | D6: 202 | E6: 201 | F6: 201 | G6: 201 | H6: 202 | I6: 199 | J6: 96 | K6: 47 | L6: 35 | M6: 76 | N6: 143 | O6: 131 | P6: 110 | Q6: 127 | R6: 96 | S6: 55 | T6: 27 | U6: 18 | V6: 58 | W6: 195 | X6: 202 | Y6: 201 | Z6: 201 | AA6: 201 | AB6: 201 | AC6: 201 | AD6: 200 | AE6: 200 | AF6: 200 | AG6: 156 | AH6: 189 | AI6: 187 | AJ6: 135 | AK6: 169 | AL6: 170 | AM6: 180 | AN6: 155 | AO6: 159 | AP6: 180 | AQ6: 185 | AR6: 206 | AS6: 210 | AT6: 207 | AU6: 203 | AV6: 185 | AW6: 166 | AX6: 153 | AY6: 155 | AZ6: 121 | BA6: 90 | BB6: 109 | BC6: 157 | BD6: 187 | BE6: 190 | BF6: 179 | BG6: 193 | BH6: 202 | BI6: 201 | BJ6: 203 | BK6: 191 | BL6: 199
A7: 202 | B7: 202 | C7: 202 | D7: 202 | E7: 201 | F7: 202 | G7: 202 | H7: 205 | I7: 170 | J7: 55 | K7: 40 | L7: 83 | M7: 171 | N7: 189 | O7: 188 | P7: 176 | Q7: 168 | R7: 160 | S7: 122 | T7: 35 | U7: 19 | V7: 27 | W7: 155 | X7: 205 | Y7: 201 | Z7: 201 | AA7: 201 | AB7: 201 | AC7: 201 | AD7: 200 | AE7: 200 | AF7: 200 | AG7: 150 | AH7: 184 | AI7: 191 | AJ7: 180 | AK7: 188 | AL7: 188 | AM7: 172 | AN7: 172 | AO7: 189 | AP7: 187 | AQ7: 199 | AR7: 213 | AS7: 208 | AT7: 204 | AU7: 198 | AV7: 120 | AW7: 74 | AX7: 63 | AY7: 55 | AZ7: 31 | BA7: 12 | BB7: 31 | BC7: 77 | BD7: 107 | BE7: 170 | BF7: 168 | BG7: 181 | BH7: 198 | BI7: 191 | BJ7: 207 | BK7: 188 | BL7: 182
A8: 202 | B8: 202 | C8: 202 | D8: 202 | E8: 202 | F8: 202 | G8: 201 | H8: 206 | I8: 151 | J8: 38 | K8: 61 | L8: 161 | M8: 195 | N8: 195 | O8: 193 | P8: 183 | Q8: 173 | R8: 162 | S8: 151 | T8: 89 | U8: 21 | V8: 16 | W8: 109 | X8: 207 | Y8: 201 | Z8: 201 | AA8: 201 | AB8: 201 | AC8: 201 | AD8: 200 | AE8: 201 | AF8: 200 | AG8: 151 | AH8: 164 | AI8: 172 | AJ8: 185 | AK8: 184 | AL8: 186 | AM8: 186 | AN8: 177 | AO8: 196 | AP8: 197 | AQ8: 217 | AR8: 205 | AS8: 208 | AT8: 183 | AU8: 98 | AV8: 47 | AW8: 34 | AX8: 15 | AY8: 16 | AZ8: 24 | BA8: 11 | BB8: 17 | BC8: 51 | BD8: 68 | BE8: 148 | BF8: 188 | BG8: 187 | BH8: 199 | BI8: 194 | BJ8: 197 | BK8: 187 | BL8: 189
A9: 201 | B9: 202 | C9: 202 | D9: 202 | E9: 202 | F9: 202 | G9: 201 | H9: 205 | I9: 164 | J9: 43 | K9: 134 | L9: 201 | M9: 200 | N9: 203 | O9: 198 | P9: 190 | Q9: 179 | R9: 165 | S9: 151 | T9: 136 | U9: 75 | V9: 18 | W9: 97 | X9: 207 | Y9: 201 | Z9: 201 | AA9: 201 | AB9: 201 | AC9: 201 | AD9: 201 | AE9: 201 | AF9: 200 | AG9: 143 | AH9: 130 | AI9: 166 | AJ9: 185 | AK9: 178 | AL9: 188 | AM9: 201 | AN9: 195 | AO9: 199 | AP9: 203 | AQ9: 214 | AR9: 207 | AS9: 189 | AT9: 103 | AU9: 54 | AV9: 41 | AW9: 25 | AX9: 9 | AY9: 8 | AZ9: 18 | BA9: 16 | BB9: 16 | BC9: 36 | BD9: 64 | BE9: 140 | BF9: 180 | BG9: 193 | BH9: 198 | BI9: 198 | BJ9: 189 | BK9: 187 | BL9: 193
A10: 202 | B10: 202 | C10: 202 | D10: 202 | E10: 202 | F10: 202 | G10: 201 | H10: 205 | I10: 169 | J10: 73 | K10: 182 | L10: 194 | M10: 184 | N10: 191 | O10: 196 | P10: 194 | Q10: 181 | R10: 154 | S10: 137 | T10: 133 | U10: 106 | V10: 33 | W10: 103 | X10: 207 | Y10: 201 | Z10: 201 | AA10: 201 | AB10: 201 | AC10: 201 | AD10: 201 | AE10: 201 | AF10: 201 | AG10: 164 | AH10: 172 | AI10: 188 | AJ10: 185 | AK10: 176 | AL10: 177 | AM10: 196 | AN10: 198 | AO10: 196 | AP10: 195 | AQ10: 191 | AR10: 212 | AS10: 139 | AT10: 56 | AU10: 40 | AV10: 31 | AW10: 56 | AX10: 80 | AY10: 73 | AZ10: 70 | BA10: 99 | BB10: 63 | BC10: 25 | BD10: 43 | BE10: 75 | BF10: 137 | BG10: 191 | BH10: 187 | BI10: 194 | BJ10: 192 | BK10: 185 | BL10: 186
A11: 201 | B11: 202 | C11: 202 | D11: 201 | E11: 202 | F11: 202 | G11: 202 | H11: 204 | I11: 180 | J11: 100 | K11: 187 | L11: 167 | M11: 155 | N11: 149 | O11: 174 | P11: 177 | Q11: 142 | R11: 121 | S11: 114 | T11: 105 | U11: 106 | V11: 48 | W11: 118 | X11: 207 | Y11: 201 | Z11: 201 | AA11: 201 | AB11: 201 | AC11: 201 | AD11: 201 | AE11: 201 | AF11: 201 | AG11: 190 | AH11: 182 | AI11: 176 | AJ11: 180 | AK11: 175 | AL11: 177 | AM11: 186 | AN11: 188 | AO11: 179 | AP11: 186 | AQ11: 195 | AR11: 182 | AS11: 71 | AT11: 52 | AU11: 49 | AV11: 106 | AW11: 180 | AX11: 194 | AY11: 187 | AZ11: 185 | BA11: 208 | BB11: 198 | BC11: 108 | BD11: 45 | BE11: 22 | BF11: 81 | BG11: 196 | BH11: 183 | BI11: 190 | BJ11: 190 | BK11: 192 | BL11: 192
A12: 202 | B12: 202 | C12: 202 | D12: 202 | E12: 202 | F12: 202 | G12: 202 | H12: 202 | I12: 195 | J12: 113 | K12: 165 | L12: 172 | M12: 134 | N12: 135 | O12: 157 | P12: 154 | Q12: 123 | R12: 139 | S12: 115 | T12: 109 | U12: 102 | V12: 48 | W12: 126 | X12: 207 | Y12: 201 | Z12: 201 | AA12: D | AB12: E | AC12: M | AD12: Y | AE12: S | AF12: T | AG12: I | AH12: F | AI12: Y | AJ12: I | AK12: N | AL12: G | AM12: 181 | AN12: 184 | AO12: 178 | AP12: 193 | AQ12: 198 | AR12: 182 | AS12: 64 | AT12: 55 | AU12: 152 | AV12: 211 | AW12: 214 | AX12: 206 | AY12: 204 | AZ12: 205 | BA12: 208 | BB12: 211 | BC12: 179 | BD12: 46 | BE12: 17 | BF12: 67 | BG12: 195 | BH12: 191 | BI12: 189 | BJ12: 189 | BK12: 189 | BL12: 196
A13: 202 | B13: 202 | C13: 202 | D13: 202 | E13: 202 | F13: 202 | G13: 202 | H13: 203 | I13: 189 | J13: 160 | K13: 183 | L13: 183 | M13: 188 | N13: 184 | O13: 180 | P13: 166 | Q13: 125 | R13: 171 | S13: 151 | T13: 134 | U13: 123 | V13: 73 | W13: 110 | X13: 194 | Y13: 202 | Z13: 201 | AA13: 201 | AB13: 201 | AC13: 201 | AD13: 201 | AE13: 201 | AF13: 201 | AG13: 176 | AH13: 184 | AI13: 171 | AJ13: 163 | AK13: 167 | AL13: 172 | AM13: 166 | AN13: 172 | AO13: 178 | AP13: 187 | AQ13: 198 | AR13: 170 | AS13: 36 | AT13: 117 | AU13: 221 | AV13: 220 | AW13: 220 | AX13: 213 | AY13: 211 | AZ13: 212 | BA13: 213 | BB13: 203 | BC13: 193 | BD13: 81 | BE13: 8 | BF13: 94 | BG13: 186 | BH13: 186 | BI13: 186 | BJ13: 182 | BK13: 188 | BL13: 187
A14: 202 | B14: 202 | C14: 202 | D14: 202 | E14: 202 | F14: 202 | G14: 202 | H14: 202 | I14: 193 | J14: 176 | K14: 194 | L14: 199 | M14: 193 | N14: 190 | O14: 201 | P14: 176 | Q14: 143 | R14: 172 | S14: 178 | T14: 160 | U14: 117 | V14: 82 | W14: 98 | X14: 189 | Y14: 203 | Z14: 201 | AA14: 201 | AB14: 201 | AC14: 201 | AG14: 179 | AK14: 150 | AL14: 142 | AM14: 151 | AN14: 151 | AO14: 161 | AP14: 172 | AQ14: 192 | AR14: 125 | AS14: 27 | AT14: 174 | AU14: 204 | AV14: 182 | AW14: 152 | AX14: 158 | AY14: 176 | AZ14: 181 | BA14: 178 | BB14: 190 | BC14: 196 | BD14: 133 | BE14: 11 | BF14: 119 | BG14: 187 | BH14: 183 | BI14: 182 | BJ14: 183 | BK14: 188 | BL14: 177
A15: 202 | B15: 202 | C15: 202 | D15: 202 | E15: 202 | F15: 202 | G15: 202 | H15: 202 | I15: 201 | J15: 188 | K15: 195 | L15: 207 | M15: 190 | N15: 178 | O15: 191 | P15: 159 | Q15: 127 | R15: 166 | S15: 181 | T15: 151 | U15: 110 | V15: 81 | W15: 121 | X15: 203 | Y15: 201 | Z15: 201 | AA15: 201 | AB15: 201 | AC15: 201 | AE15: 201 | AG15: 179 | AH15: 157 | AJ15: 149 | AK15: 149 | AL15: 123 | AM15: 148 | AN15: 168 | AO15: 161 | AP15: 177 | AQ15: 198 | AR15: 115 | AS15: 107 | AT15: 183 | AU15: 100 | AV15: 102 | AW15: 80 | AX15: 81 | AY15: 129 | AZ15: 108 | BA15: 87 | BB15: 116 | BC15: 150 | BD15: 154 | BE15: 27 | BF15: 116 | BG15: 189 | BH15: 181 | BI15: 186 | BJ15: 182 | BK15: 186 | BL15: 178
A16: 202 | B16: 202 | C16: 202 | D16: 202 | E16: 202 | F16: 202 | G16: 202 | H16: 202 | I16: 201 | J16: 197 | K16: 195 | L16: 195 | M16: 172 | N16: 184 | O16: 172 | P16: 127 | Q16: 114 | R16: 148 | S16: 160 | T16: 134 | U16: 108 | V16: 99 | W16: 175 | X16: 204 | Y16: 201 | Z16: 201 | AA16: 201 | AB16: 201 | AE16: 201 | AG16: 171 | AH16: 164 | AJ16: 165 | AK16: 135 | AL16: 125 | AM16: 151 | AN16: 174 | AO16: 165 | AP16: 184 | AQ16: 197 | AR16: 162 | AS16: 148 | AT16: 211 | AU16: 164 | AV16: 136 | AW16: 121 | AX16: 139 | AY16: 137 | AZ16: 104 | BA16: 92 | BB16: 83 | BC16: 100 | BD16: 104 | BE16: 47 | BF16: 87 | BG16: 183 | BH16: 176 | BI16: 182 | BJ16: 186 | BK16: 193 | BL16: 185
A17: 202 | B17: 202 | C17: 202 | D17: 202 | E17: 202 | F17: 202 | G17: 202 | H17: 202 | I17: 202 | J17: 199 | K17: 193 | L17: 195 | M17: 171 | N17: 151 | O17: 160 | P17: 147 | Q17: 114 | R17: 120 | S17: 150 | T17: 128 | U17: 113 | V17: 174 | W17: 202 | X17: 201 | Y17: 201 | Z17: 201 | AA17: 201 | AB17: 201 | AD17: 201 | AE17: 201 | AG17: 176 | AH17: 164 | AJ17: 148 | AK17: 113 | AL17: 134 | AM17: 123 | AN17: 158 | AO17: 170 | AP17: 177 | AQ17: 187 | AR17: 176 | AS17: 185 | AT17: 226 | AU17: 200 | AV17: 188 | AW17: 178 | AX17: 182 | AY17: 214 | AZ17: 170 | BA17: 162 | BB17: 155 | BC17: 160 | BD17: 158 | BE17: 88 | BF17: 144 | BG17: 189 | BH17: 178 | BI17: 179 | BJ17: 188 | BK17: 191 | BL17: 192
A18: 202 | B18: 202 | C18: 202 | D18: 202 | E18: 202 | F18: 202 | G18: 202 | H18: 202 | I18: 202 | J18: 202 | K18: 192 | L18: 191 | M18: 176 | N18: 160 | O18: 168 | P18: 162 | Q18: 117 | R18: 126 | S18: 150 | T18: 119 | U18: 131 | V18: 204 | W18: 201 | X18: 201 | Y18: 201 | Z18: 201 | AA18: 201 | AG18: 162 | AH18: 159 | AJ18: 134 | AK18: 104 | AL18: 122 | AM18: 161 | AN18: 168 | AO18: 177 | AP18: 170 | AQ18: 178 | AR18: 164 | AS18: 180 | AT18: 214 | AU18: 192 | AV18: 120 | AW18: 125 | AX18: 151 | AY18: 172 | AZ18: 153 | BA18: 130 | BB18: 148 | BC18: 177 | BD18: 188 | BE18: 131 | BF18: 174 | BG18: 185 | BH18: 174 | BI18: 173 | BJ18: 173 | BK18: 190 | BL18: 185
A19: 202 | B19: 202 | C19: 202 | D19: 202 | E19: 202 | F19: 202 | G19: 202 | H19: 202 | I19: 202 | J19: 202 | K19: 195 | L19: 176 | M19: 183 | N19: 194 | O19: 173 | P19: 148 | Q19: 141 | R19: 147 | S19: 127 | T19: 98 | U19: 166 | V19: 204 | W19: 201 | X19: 201 | Y19: 201 | Z19: 201 | AA19: 201 | AC19: 201 | AD19: 201 | AE19: 201 | AG19: 152 | AH19: 160 | AJ19: 119 | AK19: 145 | AL19: 161 | AM19: 177 | AN19: 170 | AO19: 145 | AP19: 158 | AQ19: 165 | AR19: 153 | AS19: 122 | AT19: 159 | AU19: 138 | AV19: 68 | AW19: 116 | AX19: 84 | AY19: 69 | AZ19: 66 | BA19: 122 | BB19: 117 | BC19: 161 | BD19: 172 | BE19: 141 | BF19: 168 | BG19: 174 | BH19: 180 | BI19: 175 | BJ19: 176 | BK19: 179 | BL19: 160
A20: 202 | B20: 202 | C20: 202 | D20: 202 | E20: 202 | F20: 202 | G20: 202 | H20: 202 | I20: 202 | J20: 201 | K20: 203 | L20: 182 | M20: 163 | N20: 188 | O20: 186 | P20: 174 | Q20: 159 | R20: 127 | S20: 91 | T20: 88 | U20: 186 | V20: 204 | W20: 201 | X20: 201 | Y20: 201 | Z20: 201 | AA20: 201 | AC20: 201 | AD20: 201 | AE20: 201 | AG20: 164 | AH20: 167 | AJ20: 111 | AK20: 121 | AL20: 168 | AM20: 161 | AN20: 162 | AO20: 148 | AP20: 161 | AQ20: 169 | AR20: 157 | AS20: 77 | AT20: 77 | AU20: 128 | AV20: 53 | AW20: 101 | AX20: 152 | AY20: 144 | AZ20: 100 | BA20: 55 | BB20: 62 | BC20: 137 | BD20: 121 | BE20: 109 | BF20: 169 | BG20: 166 | BH20: 175 | BI20: 180 | BJ20: 170 | BK20: 165 | BL20: 155
A21: 202 | B21: 202 | C21: 202 | D21: 202 | E21: 202 | F21: 202 | G21: 202 | H21: 202 | I21: 202 | J21: 202 | K21: 202 | L21: 197 | M21: 162 | N21: 147 | O21: 135 | P21: 129 | Q21: 117 | R21: 91 | S21: 82 | T21: 84 | U21: 97 | V21: 189 | W21: 203 | X21: 201 | Y21: 201 | Z21: 201 | AC21: 201 | AD21: 201 | AG21: 151 | AK21: 160 | AL21: 147 | AM21: 158 | AN21: 155 | AO21: 165 | AP21: 165 | AQ21: 171 | AR21: 163 | AS21: 81 | AT21: 42 | AU21: 74 | AV21: 131 | AW21: 201 | AX21: 184 | AY21: 191 | AZ21: 167 | BA21: 117 | BB21: 85 | BC21: 100 | BD21: 50 | BE21: 105 | BF21: 160 | BG21: 174 | BH21: 173 | BI21: 175 | BJ21: 158 | BK21: 159 | BL21: 165
A22: 202 | B22: 202 | C22: 202 | D22: 202 | E22: 202 | F22: 202 | G22: 202 | H22: 202 | I22: 202 | J22: 202 | K22: 203 | L22: 185 | M22: 180 | N22: 168 | O22: 139 | P22: 121 | Q22: 109 | R22: 97 | S22: 94 | T22: 94 | U22: 41 | V22: 140 | W22: 205 | X22: 201 | Y22: 201 | Z22: 201 | AA22: 201 | AB22: 201 | AC22: 201 | AD22: 201 | AE22: 200 | AF22: 201 | AG22: 125 | AH22: 92 | AI22: 118 | AJ22: 143 | AK22: 161 | AL22: 160 | AM22: 169 | AN22: 153 | AO22: 160 | AP22: 166 | AQ22: 170 | AR22: 147 | AS22: 78 | AT22: 40 | AU22: 39 | AV22: 134 | AW22: 195 | AX22: 127 | AY22: 101 | AZ22: 151 | BA22: 187 | BB22: 81 | BC22: 22 | BD22: 43 | BE22: 146 | BF22: 144 | BG22: 174 | BH22: 176 | BI22: 164 | BJ22: 154 | BK22: 154 | BL22: 159
A23: 202 | B23: 202 | C23: 202 | D23: 202 | E23: 202 | F23: 202 | G23: 202 | H23: 202 | I23: 202 | J23: 202 | K23: 205 | L23: 141 | M23: 180 | N23: 193 | O23: 190 | P23: 159 | Q23: 123 | R23: 113 | S23: 110 | T23: 94 | U23: 68 | V23: 93 | W23: 198 | X23: 202 | Y23: 201 | Z23: 201 | AA23: 201 | AB23: B | AC23: L | AD23: A | AE23: C | AF23: K | AG23: B | AH23: O | AI23: X | AJ23: 142 | AK23: 135 | AL23: 151 | AM23: 159 | AN23: 152 | AO23: 153 | AP23: 157 | AQ23: 153 | AR23: 83 | AS23: 85 | AT23: 109 | AU23: 27 | AV23: 68 | AW23: 156 | AX23: 148 | AY23: 147 | AZ23: 176 | BA23: 128 | BB23: 27 | BC23: 17 | BD23: 117 | BE23: 145 | BF23: 158 | BG23: 172 | BH23: 167 | BI23: 152 | BJ23: 153 | BK23: 138 | BL23: 86
A24: 202 | B24: 202 | C24: 202 | D24: 202 | E24: 202 | F24: 202 | G24: 202 | H24: 202 | I24: 203 | J24: 200 | K24: 186 | L24: 146 | M24: 168 | N24: 193 | O24: 193 | P24: 152 | Q24: 128 | R24: 125 | S24: 114 | T24: 87 | U24: 74 | V24: 77 | W24: 172 | X24: 205 | Y24: 202 | Z24: 201 | AA24: 201 | AB24: 201 | AC24: 201 | AD24: 201 | AE24: 201 | AF24: 201 | AG24: 67 | AH24: 77 | AI24: 124 | AJ24: 149 | AK24: 138 | AL24: 138 | AM24: 156 | AN24: 159 | AO24: 133 | AP24: 102 | AQ24: 103 | AR24: 46 | AS24: 67 | AT24: 174 | AU24: 63 | AV24: 24 | AW24: 33 | AX24: 47 | AY24: 55 | AZ24: 56 | BA24: 21 | BB24: 11 | BC24: 87 | BD24: 135 | BE24: 129 | BF24: 142 | BG24: 137 | BH24: 143 | BI24: 142 | BJ24: 145 | BK24: 92 | BL24: 55
A25: 202 | B25: 202 | C25: 202 | D25: 202 | E25: 203 | F25: 201 | G25: 197 | H25: 204 | I25: 187 | J25: 151 | K25: 148 | L25: 155 | M25: 149 | N25: 171 | O25: 180 | P25: 157 | Q25: 141 | R25: 127 | S25: 92 | T25: 76 | U25: 76 | V25: 76 | W25: 106 | X25: 162 | Y25: 197 | Z25: 203 | AA25: 201 | AB25: 201 | AC25: 201 | AD25: 201 | AE25: 201 | AF25: 201 | AG25: 128 | AH25: 105 | AI25: 135 | AJ25: 149 | AK25: 140 | AL25: 154 | AM25: 152 | AN25: 140 | AO25: 75 | AP25: 106 | AQ25: 97 | AR25: 50 | AS25: 23 | AT25: 135 | AU25: 146 | AV25: 36 | AW25: 6 | AX25: 7 | AY25: 16 | AZ25: 11 | BA25: 9 | BB25: 70 | BC25: 111 | BD25: 147 | BE25: 142 | BF25: 144 | BG25: 127 | BH25: 142 | BI25: 137 | BJ25: 128 | BK25: 65 | BL25: 62
A26: 202 | B26: 202 | C26: 202 | D26: 203 | E26: 195 | F26: 168 | G26: 155 | H26: 172 | I26: 146 | J26: 141 | K26: 146 | L26: 151 | M26: 151 | N26: 132 | O26: 142 | P26: 145 | Q26: 127 | R26: 85 | S26: 77 | T26: 78 | U26: 81 | V26: 96 | W26: 108 | X26: 115 | Y26: 156 | Z26: 191 | AA26: 202 | AB26: 202 | AC26: 201 | AD26: 201 | AE26: 200 | AF26: 200 | AG26: 194 | AH26: 137 | AI26: 169 | AJ26: 172 | AK26: 161 | AL26: 146 | AM26: 129 | AN26: 103 | AO26: 83 | AP26: 109 | AQ26: 90 | AR26: 83 | AS26: 35 | AT26: 40 | AU26: 147 | AV26: 115 | AW26: 51 | AX26: 27 | AY26: 27 | AZ26: 39 | BA26: 73 | BB26: 89 | BC26: 36 | BD26: 104 | BE26: 158 | BF26: 138 | BG26: 145 | BH26: 111 | BI26: 81 | BJ26: 80 | BK26: 44 | BL26: 71
A27: 202 | B27: 203 | C27: 203 | D27: 184 | E27: 147 | F27: 142 | G27: 145 | H27: 150 | I27: 141 | J27: 147 | K27: 140 | L27: 146 | M27: 150 | N27: 95 | O27: 120 | P27: 71 | Q27: 78 | R27: 69 | S27: 82 | T27: 89 | U27: 104 | V27: 118 | W27: 117 | X27: 119 | Y27: 124 | Z27: 128 | AA27: 146 | AB27: 190 | AC27: 203 | AD27: 201 | AE27: 200 | AF27: 200 | AG27: 206 | AH27: 179 | AI27: 161 | AJ27: 142 | AK27: 122 | AL27: 111 | AM27: 89 | AN27: 89 | AO27: 94 | AP27: 111 | AQ27: 94 | AR27: 87 | AS27: 76 | AT27: 34 | AU27: 48 | AV27: 88 | AW27: 88 | AX27: 71 | AY27: 68 | AZ27: 79 | BA27: 75 | BB27: 37 | BC27: 16 | BD27: 47 | BE27: 89 | BF27: 133 | BG27: 111 | BH27: 83 | BI27: 94 | BJ27: 85 | BK27: 37 | BL27: 61
A28: 202 | B28: 195 | C28: 178 | D28: 143 | E28: 137 | F28: 141 | G28: 144 | H28: 152 | I28: 146 | J28: 138 | K28: 139 | L28: 143 | M28: 166 | N28: 69 | O28: 78 | P28: 79 | Q28: 84 | R28: 97 | S28: 106 | T28: 112 | U28: 124 | V28: 125 | W28: 120 | X28: 116 | Y28: 120 | Z28: 123 | AA28: 119 | AB28: 132 | AC28: 159 | AD28: 197 | AE28: 202 | AF28: 200 | AG28: 158 | AH28: 144 | AI28: 130 | AJ28: 105 | AK28: 91 | AL28: 86 | AM28: 95 | AN28: 86 | AO28: 104 | AP28: 106 | AQ28: 100 | AR28: 88 | AS28: 87 | AT28: 68 | AU28: 59 | AV28: 65 | AW28: 59 | AX28: 57 | AY28: 55 | AZ28: 48 | BA28: 41 | BB28: 47 | BC28: 53 | BD28: 64 | BE28: 66 | BF28: 76 | BG28: 102 | BH28: 101 | BI28: 70 | BJ28: 58 | BK28: 54 | BL28: 38
A29: 192 | B29: 164 | C29: 148 | D29: 127 | E29: 137 | F29: 137 | G29: 141 | H29: 152 | I29: 142 | J29: 135 | K29: 143 | L29: 141 | M29: 131 | N29: 103 | O29: 120 | P29: 120 | Q29: 109 | R29: 124 | S29: 119 | T29: 123 | U29: 127 | V29: 126 | W29: 119 | X29: 116 | Y29: 126 | Z29: 126 | AA29: 124 | AB29: 124 | AC29: 124 | AD29: 136 | AE29: 193 | AF29: 204 | AG29: 123 | AH29: 114 | AI29: 109 | AJ29: 91 | AK29: 84 | AL29: 72 | AM29: 103 | AN29: 87 | AO29: 107 | AP29: 105 | AQ29: 100 | AR29: 86 | AS29: 92 | AT29: 77 | AU29: 81 | AV29: 96 | AW29: 75 | AX29: 54 | AY29: 55 | AZ29: 57 | BA29: 61 | BB29: 60 | BC29: 78 | BD29: 55 | BE29: 67 | BF29: 69 | BG29: 66 | BH29: 89 | BI29: 50 | BJ29: 32 | BK29: 57 | BL29: 32
A30: 168 | B30: 148 | C30: 138 | D30: 122 | E30: 136 | F30: 133 | G30: 139 | H30: 153 | I30: 139 | J30: 138 | K30: 144 | L30: 138 | M30: 124 | N30: 131 | O30: 129 | P30: 122 | Q30: 113 | R30: 115 | S30: 123 | T30: 124 | U30: 129 | V30: 130 | W30: 117 | X30: 119 | Y30: 128 | Z30: 127 | AA30: 119 | AB30: 126 | AC30: 123 | AD30: 114 | AE30: 127 | AF30: 173 | AG30: 116 | AH30: 98 | AI30: 98 | AJ30: 90 | AK30: 80 | AL30: 80 | AM30: 105 | AN30: 86 | AO30: 115 | AP30: 97 | AQ30: 99 | AR30: 86 | AS30: 95 | AT30: 82 | AU30: 86 | AV30: 99 | AW30: 93 | AX30: 69 | AY30: 73 | AZ30: 73 | BA30: 70 | BB30: 68 | BC30: 89 | BD30: 65 | BE30: 69 | BF30: 64 | BG30: 58 | BH30: 49 | BI30: 40 | BJ30: 37 | BK30: 44 | BL30: 45
A31: 154 | B31: 142 | C31: 133 | D31: 121 | E31: 135 | F31: 131 | G31: 142 | H31: 152 | I31: 136 | J31: 137 | K31: 142 | L31: 140 | M31: 136 | N31: 134 | O31: 123 | P31: 116 | Q31: 123 | R31: 140 | S31: 128 | T31: 126 | U31: 131 | V31: 130 | W31: 115 | X31: 121 | Y31: 128 | Z31: 125 | AA31: 121 | AB31: 111 | AC31: 120 | AD31: 109 | AE31: 104 | AF31: 102 | AG31: 108 | AH31: 94 | AI31: 88 | AJ31: 87 | AK31: 78 | AL31: 92 | AM31: 89 | AN31: 92 | AO31: 111 | AP31: 86 | AQ31: 104 | AR31: 86 | AS31: 95 | AT31: 89 | AU31: 88 | AV31: 106 | AW31: 104 | AX31: 76 | AY31: 79 | AZ31: 79 | BA31: 75 | BB31: 77 | BC31: 101 | BD31: 70 | BE31: 70 | BF31: 64 | BG31: 57 | BH31: 49 | BI31: 48 | BJ31: 48 | BK31: 23 | BL31: 49
A32: 150 | B32: 135 | C32: 129 | D32: 122 | E32: 134 | F32: 133 | G32: 145 | H32: 149 | I32: 134 | J32: 137 | K32: 140 | L32: 140 | M32: 137 | N32: 136 | O32: 167 | P32: 126 | Q32: 138 | R32: 135 | S32: 125 | T32: 129 | U32: 136 | V32: 130 | W32: 116 | X32: 122 | Y32: 125 | Z32: 123 | AA32: 114 | AB32: 103 | AC32: 118 | AD32: 102 | AE32: 100 | AF32: 92 | AG32: 108 | AH32: 87 | AI32: 77 | AJ32: 78 | AK32: 90 | AL32: 85 | AM32: 82 | AN32: 95 | AO32: 94 | AP32: 89 | AQ32: 101 | AR32: 89 | AS32: 95 | AT32: 94 | AU32: 91 | AV32: 111 | AW32: 111 | AX32: 80 | AY32: 84 | AZ32: 81 | BA32: 79 | BB32: 79 | BC32: 108 | BD32: 83 | BE32: 76 | BF32: 63 | BG32: 58 | BH32: 46 | BI32: 61 | BJ32: 65 | BK32: 49 | BL32: 19
X34: T | Y34: o | Z34: m | AB34: Y | AC34: e | AD34: h | AI34: J | AJ34: u | AK34: b | AL34: a | AM34: i | AN34: r
X36: C | Y36: S | AA36: P | AB36: R | AC36: O | AD36: F | AI36: P | AJ36: h | AK36: D | AM36: S | AN36: T | AO36: U | AP36: D | AQ36: E | AR36: N | AS36: T
U38: C | V38: U | X38: B | Y38: O | Z38: U | AA38: L | AB38: D | AC38: E | AD38: R | AI38: C | AJ38: U | AL38: B | AM38: O | AN38: U | AO38: L | AP38: D | AQ38: E | AR38: R
U40: A | V40: I | W40: - | X40: B | Y40: Y | Z40: - | AA40: H | AB40: A | AC40: N | AD40: D | AI40: A | AJ40: I | AK40: . | AL40: X | AM40: A | AN40: I | AO40: . | AP40: V | AQ40: I | AR40: S
AE47: Contents
AF48: Dataset
AF49: Perceptron (core of Neural Nets)
AF50: Multilayer Perceptron
...

Sheet Dataset-Tumor
B2: D | C2: A | D2: T | E2: A | F2: S | G2: E | H2: T | J2: 2D | K2: M | L2: R | M2: I | P2: Brain Tumor | T2: https://www.kaggle.com/datasets/masoudnickparvar/brain-tumor-mri-dataset/data
L4: Sample | M4: #1 | AF4: Sample | AG4: #2 | AZ4: Sample | BA4: #3 | BT4: Sample | BU4: #4
C5: Class 1 | D5: 2 | E5: 2 | F5: 2 | G5: 2 | H5: 2 | I5: 2 | J5: 2 | K5: 2 | L5: 2 | M5: 2 | N5: 2 | O5: 2 | P5: 2 | Q5: 2 | R5: 2 | S5: 2 | T5: 2 | U5: 2 | V5: 2 | W5: 2 | X5: 2 | Y5: 2 | Z5: 2 | AA5: 2 | AB5: 2 | AC5: 2 | AD5: 2 | AE5: 0 | AF5: 0 | AG5: 0 | AH5: 0 | AI5: 0 | AJ5: 1 | AK5: 2 | AL5: 2 | AM5: 2 | AN5: 2 | AO5: 2 | AP5: 2 | AQ5: 2 | AR5: 2 | AS5: 2 | AT5: 2 | AU5: 2 | AV5: 2 | AW5: 2 | AX5: 2 | AY5: 2 | AZ5: 2 | BA5: 2 | BB5: 2 | BC5: 2 | BD5: 2 | BE5: 2 | BF5: 2 | BG5: 2 | BH5: 2 | BI5: 2 | BJ5: 2 | BK5: 2 | BL5: 2 | BM5: 2 | BN5: 2 | BO5: 3 | BP5: 3 | BQ5: 3 | BR5: 2 | BS5: 2 | BT5: 3 | BU5: 3 | BV5: 3 | BW5: 3 | BX5: 3 | BY5: 3 | BZ5: 3 | CA5: 3 | CB5: 3 | CC5: 3 | CD5: 3 | CE5: 2 | CG5: Class ID | CH5: SID
C6: Glioma | D6: 2 | E6: 2 | F6: 2 | G6: 2 | H6: 2 | I6: 2 | J6: 1 | K6: 0 | L6: 0 | M6: 0 | N6: 0 | O6: 0 | P6: 0 | Q6: 2 | R6: 2 | S6: 2 | T6: 2 | U6: 2 | V6: 2 | W6: 2 | X6: 3 | Y6: 3 | Z6: 3 | AA6: 3 | AB6: 3 | AC6: 2 | AD6: 1 | AE6: 15 | AF6: 36 | AG6: 43 | AH6: 45 | AI6: 25 | AJ6: 3 | AK6: 1 | AL6: 3 | AM6: 3 | AN6: 3 | AO6: 3 | AP6: 3 | AQ6: 3 | AR6: 2 | AS6: 2 | AT6: 2 | AU6: 2 | AV6: 2 | AW6: 2 | AX6: 1 | AY6: 0 | AZ6: 0 | BA6: 0 | BB6: 0 | BC6: 0 | BD6: 0 | BE6: 2 | BF6: 2 | BG6: 2 | BH6: 2 | BI6: 2 | BJ6: 2 | BK6: 2 | BL6: 4 | BM6: 4 | BN6: 4 | BO6: 4 | BP6: 4 | BQ6: 3 | BR6: 3 | BS6: 3 | BT6: 3 | BU6: 3 | BV6: 3 | BW6: 3 | BX6: 3 | BY6: 3 | BZ6: 3 | CA6: 3 | CB6: 3 | CC6: 3 | CD6: 3 | CE6: 3 | CG6: 1 | CH6: 1
D7: 2 | E7: 3 | F7: 3 | G7: 2 | H7: 2 | I7: 0 | J7: 7 | K7: 33 | L7: 66 | M7: 80 | N7: 83 | O7: 61 | P7: 22 | Q7: 0 | R7: 1 | S7: 3 | T7: 2 | U7: 3 | V7: 3 | W7: 2 | X7: 5 | Y7: 6 | Z7: 5 | AA7: 5 | AB7: 3 | AC7: 16 | AD7: 79 | AE7: 117 | AF7: 103 | AG7: 87 | AH7: 107 | AI7: 121 | AJ7: 92 | AK7: 30 | AL7: 4 | AM7: 6 | AN7: 6 | AO7: 5 | AP7: 5 | AQ7: 5 | AR7: 2 | AS7: 3 | AT7: 3 | AU7: 2 | AV7: 2 | AW7: 0 | AX7: 7 | AY7: 33 | AZ7: 66 | BA7: 80 | BB7: 83 | BC7: 61 | BD7: 22 | BE7: 0 | BF7: 1 | BG7: 3 | BH7: 2 | BI7: 3 | BJ7: 3 | BK7: 2 | BL7: 4 | BM7: 4 | BN7: 4 | BO7: 4 | BP7: 4 | BQ7: 3 | BR7: 3 | BS7: 3 | BT7: 3 | BU7: 1 | BV7: 0 | BW7: 0 | BX7: 0 | BY7: 0 | BZ7: 0 | CA7: 2 | CB7: 3 | CC7: 3 | CD7: 3 | CE7: 3 | CG7: 2 | CH7: 2
D8: 2 | E8: 4 | F8: 3 | G8: 2 | H8: 9 | I8: 51 | J8: 104 | K8: 104 | L8: 87 | M8: 71 | N8: 81 | O8: 99 | P8: 115 | Q8: 78 | R8: 13 | S8: 2 | T8: 4 | U8: 3 | V8: 4 | W8: 2 | X8: 4 | Y8: 6 | Z8: 6 | AA8: 5 | AB8: 46 | AC8: 116 | AD8: 120 | AE8: 76 | AF8: 61 | AG8: 73 | AH8: 57 | AI8: 64 | AJ8: 99 | AK8: 117 | AL8: 57 | AM8: 6 | AN8: 7 | AO8: 7 | AP8: 7 | AQ8: 4 | AR8: 2 | AS8: 4 | AT8: 3 | AU8: 2 | AV8: 9 | AW8: 51 | AX8: 104 | AY8: 104 | AZ8: 87 | BA8: 71 | BB8: 81 | BC8: 99 | BD8: 115 | BE8: 78 | BF8: 13 | BG8: 2 | BH8: 4 | BI8: 3 | BJ8: 4 | BK8: 2 | BL8: 4 | BM8: 4 | BN8: 4 | BO8: 4 | BP8: 4 | BQ8: 4 | BR8: 3 | BS8: 0 | BT8: 2 | BU8: 16 | BV8: 31 | BW8: 43 | BX8: 49 | BY8: 46 | BZ8: 33 | CA8: 9 | CB8: 0 | CC8: 3 | CD8: 4 | CE8: 4 | CG8: 3 | CH8: 3
D9: 2 | E9: 6 | F9: 4 | G9: 12 | H9: 110 | I9: 129 | J9: 82 | K9: 53 | L9: 57 | M9: 77 | N9: 46 | O9: 46 | P9: 70 | Q9: 107 | R9: 99 | S9: 15 | T9: 3 | U9: 5 | V9: 5 | W9: 2 | X9: 3 | Y9: 7 | Z9: 3 | AA9: 53 | AB9: 137 | AC9: 99 | AD9: 54 | AE9: 53 | AF9: 59 | AG9: 68 | AH9: 56 | AI9: 55 | AJ9: 53 | AK9: 74 | AL9: 112 | AM9: 66 | AN9: 5 | AO9: 6 | AP9: 7 | AQ9: 3 | AR9: 2 | AS9: 6 | AT9: 4 | AU9: 12 | AV9: 110 | AW9: 129 | AX9: 82 | AY9: 53 | AZ9: 57 | BA9: 77 | BB9: 46 | BC9: 46 | BD9: 70 | BE9: 107 | BF9: 99 | BG9: 15 | BH9: 3 | BI9: 5 | BJ9: 5 | BK9: 2 | BL9: 5 | BM9: 5 | BN9: 4 | BO9: 4 | BP9: 4 | BQ9: 2 | BR9: 3 | BS9: 40 | BT9: 88 | BU9: 104 | BV9: 102 | BW9: 103 | BX9: 103 | BY9: 105 | BZ9: 115 | CA9: 113 | CB9: 49 | CC9: 4 | CD9: 3 | CE9: 4 | CG9: 4 | CH9: 4
D10: 1 | E10: 6 | F10: 0 | G10: 71 | H10: 130 | I10: 66 | J10: 48 | K10: 49 | L10: 59 | M10: 79 | N10: 53 | O10: 47 | P10: 48 | Q10: 56 | R10: 95 | S10: 90 | T10: 9 | U10: 4 | V10: 6 | W10: 1 | X10: 1 | Y10: 4 | Z10: 25 | AA10: 116 | AB10: 85 | AC10: 57 | AD10: 57 | AE10: 63 | AF10: 67 | AG10: 64 | AH10: 62 | AI10: 58 | AJ10: 53 | AK10: 51 | AL10: 62 | AM10: 99 | AN10: 44 | AO10: 4 | AP10: 7 | AQ10: 1 | AR10: 1 | AS10: 6 | AT10: 0 | AU10: 71 | AV10: 130 | AW10: 66 | AX10: 48 | AY10: 49 | AZ10: 59 | BA10: 79 | BB10: 53 | BC10: 47 | BD10: 48 | BE10: 56 | BF10: 95 | BG10: 90 | BH10: 9 | BI10: 4 | BJ10: 6 | BK10: 1 | BL10: 5 | BM10: 5 | BN10: 4 | BO10: 4 | BP10: 1 | BQ10: 17 | BR10: 78 | BS10: 91 | BT10: 67 | BU10: 72 | BV10: 63 | BW10: 62 | BX10: 59 | BY10: 56 | BZ10: 61 | CA10: 91 | CB10: 131 | CC10: 72 | CD10: 3 | CE10: 3
D11: 0 | E11: 4 | F11: 16 | G11: 111 | H11: 74 | I11: 53 | J11: 52 | K11: 60 | L11: 62 | M11: 59 | N11: 60 | O11: 57 | P11: 48 | Q11: 47 | R11: 65 | S11: 102 | T11: 68 | U11: 2 | V11: 5 | W11: 1 | X11: 0 | Y11: 2 | Z11: 80 | AA11: 91 | AB11: 63 | AC11: 59 | AD11: 66 | AE11: 70 | AF11: 73 | AG11: 71 | AH11: 64 | AI11: 61 | AJ11: 60 | AK11: 55 | AL11: 53 | AM11: 66 | AN11: 81 | AO11: 9 | AP11: 5 | AQ11: 0 | AR11: 0 | AS11: 4 | AT11: 16 | AU11: 111 | AV11: 74 | AW11: 53 | AX11: 52 | AY11: 60 | AZ11: 62 | BA11: 59 | BB11: 60 | BC11: 57 | BD11: 48 | BE11: 47 | BF11: 65 | BG11: 102 | BH11: 68 | BI11: 2 | BJ11: 5 | BK11: 1 | BL11: 5 | BM11: 5 | BN11: 5 | BO11: 1 | BP11: 26 | BQ11: 87 | BR11: 86 | BS11: 65 | BT11: 63 | BU11: 73 | BV11: 74 | BW11: 74 | BX11: 76 | BY11: 70 | BZ11: 66 | CA11: 57 | CB11: 72 | CC11: 129 | CD11: 37 | CE11: 1
D12: 0 | E12: 0 | F12: 53 | G12: 94 | H12: 58 | I12: 55 | J12: 59 | K12: 67 | L12: 69 | M12: 66 | N12: 66 | O12: 61 | P12: 68 | Q12: 71 | R12: 54 | S12: 52 | T12: 73 | U12: 13 | V12: 3 | W12: 0 | X12: 0 | Y12: 20 | Z12: 102 | AA12: 70 | AB12: 63 | AC12: 67 | AD12: 72 | AE12: 76 | AF12: 77 | AG12: 74 | AH12: 66 | AI12: 66 | AJ12: 99 | AK12: 92 | AL12: 58 | AM12: 57 | AN12: 83 | AO12: 30 | AP12: 2 | AQ12: 0 | AR12: 0 | AS12: 0 | AT12: 53 | AU12: 94 | AV12: 58 | AW12: 55 | AX12: 59 | AY12: 67 | AZ12: 69 | BA12: 66 | BB12: 66 | BC12: 61 | BD12: 68 | BE12: 71 | BF12: 54 | BG12: 52 | BH12: 73 | BI12: 13 | BJ12: 3 | BK12: 0 | BL12: 5 | BM12: 5 | BN12: 4 | BO12: 14 | BP12: 96 | BQ12: 79 | BR12: 82 | BS12: 70 | BT12: 70 | BU12: 81 | BV12: 81 | BW12: 79 | BX12: 79 | BY12: 79 | BZ12: 76 | CA12: 66 | CB12: 57 | CC12: 93 | CD12: 88 | CE12: 1
D13: 0 | E13: 0 | F13: 77 | G13: 81 | H13: 54 | I13: 61 | J13: 68 | K13: 72 | L13: 72 | M13: 69 | N13: 67 | O13: 81 | P13: 100 | Q13: 96 | R13: 54 | S13: 12 | T13: 65 | U13: 26 | V13: 2 | W13: 0 | X13: 0 | Y13: 50 | Z13: 101 | AA13: 62 | AB13: 68 | AC13: 73 | AD13: 77 | AE13: 62 | AF13: 60 | AG13: 74 | AH13: 63 | AI13: 94 | AJ13: 120 | AK13: 106 | AL13: 70 | AM13: 49 | AN13: 73 | AO13: 63 | AP13: 0 | AQ13: 0 | AR13: 0 | AS13: 0 | AT13: 77 | AU13: 81 | AV13: 54 | AW13: 61 | AX13: 68 | AY13: 72 | AZ13: 72 | BA13: 69 | BB13: 67 | BC13: 81 | BD13: 100 | BE13: 96 | BF13: 54 | BG13: 12 | BH13: 65 | BI13: 26 | BJ13: 2 | BK13: 0 | BL13: 5 | BM13: 5 | BN13: 1 | BO13: 73 | BP13: 98 | BQ13: 71 | BR13: 74 | BS13: 70 | BT13: 77 | BU13: 80 | BV13: 74 | BW13: 73 | BX13: 76 | BY13: 82 | BZ13: 74 | CA13: 71 | CB13: 64 | CC13: 61 | CD13: 112 | CE13: 10
D14: 0 | E14: 0 | F14: 91 | G14: 66 | H14: 60 | I14: 65 | J14: 73 | K14: 74 | L14: 72 | M14: 69 | N14: 70 | O14: 88 | P14: 71 | Q14: 93 | R14: 91 | S14: 49 | T14: 108 | U14: 34 | V14: 1 | W14: 0 | X14: 0 | Y14: 82 | Z14: 102 | AA14: 65 | AB14: 69 | AC14: 77 | AD14: 78 | AE14: 68 | AF14: 63 | AG14: 81 | AH14: 75 | AI14: 118 | AJ14: 79 | AK14: 91 | AL14: 96 | AM14: 68 | AN14: 71 | AO14: 83 | AP14: 2 | AQ14: 0 | AR14: 0 | AS14: 0 | AT14: 91 | AU14: 66 | AV14: 60 | AW14: 65 | AX14: 73 | AY14: 74 | AZ14: 72 | BA14: 69 | BB14: 70 | BC14: 88 | BD14: 71 | BE14: 93 | BF14: 91 | BG14: 49 | BH14: 108 | BI14: 34 | BJ14: 1 | BK14: 0 | BL14: 5 | BM14: 3 | BN14: 22 | BO14: 122 | BP14: 95 | BQ14: 70 | BR14: 69 | BS14: 71 | BT14: 73 | BU14: 70 | BV14: 70 | BW14: 80 | BX14: 76 | BY14: 75 | BZ14: 74 | CA14: 76 | CB14: 70 | CC14: 53 | CD14: 116 | CE14: 18
D15: 0 | E15: 0 | F15: 106 | G15: 67 | H15: 62 | I15: 68 | J15: 72 | K15: 72 | L15: 72 | M15: 70 | N15: 67 | O15: 92 | P15: 106 | Q15: 96 | R15: 79 | S15: 56 | T15: 113 | U15: 36 | V15: 0 | W15: 0 | X15: 0 | Y15: 97 | Z15: 83 | AA15: 65 | AB15: 71 | AC15: 77 | AD15: 78 | AE15: 84 | AF15: 78 | AG15: 81 | AH15: 69 | AI15: 120 | AJ15: 82 | AK15: 72 | AL15: 108 | AM15: 104 | AN15: 65 | AO15: 104 | AP15: 9 | AQ15: 0 | AR15: 0 | AS15: 0 | AT15: 106 | AU15: 67 | AV15: 62 | AW15: 68 | AX15: 72 | AY15: 72 | AZ15: 72 | BA15: 70 | BB15: 67 | BC15: 92 | BD15: 106 | BE15: 96 | BF15: 79 | BG15: 56 | BH15: 113 | BI15: 36 | BJ15: 0 | BK15: 0 | BL15: 5 | BM15: 3 | BN15: 68 | BO15: 86 | BP15: 86 | BQ15: 72 | BR15: 75 | BS15: 87 | BT15: 70 | BU15: 72 | BV15: 80 | BW15: 86 | BX15: 88 | BY15: 64 | BZ15: 24 | CA15: 64 | CB15: 73 | CC15: 50 | CD15: 118 | CE15: 25
D16: 0 | E16: 0 | F16: 111 | G16: 72 | H16: 59 | I16: 69 | J16: 69 | K16: 73 | L16: 75 | M16: 76 | N16: 71 | O16: 69 | P16: 74 | Q16: 77 | R16: 70 | S16: 47 | T16: 107 | U16: 34 | V16: 0 | W16: 0 | X16: 0 | Y16: 96 | Z16: 62 | AA16: 66 | AB16: 72 | AC16: 79 | AD16: 81 | AE16: 80 | AF16: 78 | AG16: 76 | AH16: 66 | AI16: 105 | AJ16: 106 | AK16: 78 | AL16: 72 | AM16: 87 | AN16: 54 | AO16: 116 | AP16: 18 | AQ16: 0 | AR16: 0 | AS16: 0 | AT16: 111 | AU16: 72 | AV16: 59 | AW16: 69 | AX16: 69 | AY16: 73 | AZ16: 75 | BA16: 76 | BB16: 71 | BC16: 69 | BD16: 74 | BE16: 77 | BF16: 70 | BG16: 47 | BH16: 107 | BI16: 34 | BJ16: 0 | BK16: 0 | BL16: 4 | BM16: 7 | BN16: 84 | BO16: 64 | BP16: 69 | BQ16: 84 | BR16: 73 | BS16: 68 | BT16: 73 | BU16: 78 | BV16: 69 | BW16: 73 | BX16: 92 | BY16: 66 | BZ16: 36 | CA16: 64 | CB16: 70 | CC16: 53 | CD16: 125 | CE16: 23
D17: 0 | E17: 1 | F17: 113 | G17: 76 | H17: 62 | I17: 66 | J17: 70 | K17: 73 | L17: 74 | M17: 72 | N17: 69 | O17: 69 | P17: 59 | Q17: 56 | R17: 57 | S17: 55 | T17: 105 | U17: 29 | V17: 0 | W17: 0 | X17: 0 | Y17: 96 | Z17: 63 | AA17: 63 | AB17: 74 | AC17: 79 | AD17: 77 | AE17: 77 | AF17: 74 | AG17: 70 | AH17: 64 | AI17: 74 | AJ17: 97 | AK17: 85 | AL17: 70 | AM17: 91 | AN17: 45 | AO17: 96 | AP17: 16 | AQ17: 0 | AR17: 0 | AS17: 1 | AT17: 113 | AU17: 76 | AV17: 62 | AW17: 66 | AX17: 70 | AY17: 73 | AZ17: 74 | BA17: 72 | BB17: 69 | BC17: 69 | BD17: 59 | BE17: 56 | BF17: 57 | BG17: 55 | BH17: 105 | BI17: 29 | BJ17: 0 | BK17: 0 | BL17: 5 | BM17: 5 | BN17: 68 | BO17: 103 | BP17: 97 | BQ17: 64 | BR17: 83 | BS17: 82 | BT17: 76 | BU17: 77 | BV17: 73 | BW17: 72 | BX17: 69 | BY17: 74 | BZ17: 80 | CA17: 85 | CB17: 66 | CC17: 51 | CD17: 125 | CE17: 13
D18: 0 | E18: 3 | F18: 96 | G18: 62 | H18: 92 | I18: 72 | J18: 70 | K18: 74 | L18: 75 | M18: 71 | N18: 71 | O18: 72 | P18: 67 | Q18: 62 | R18: 68 | S18: 42 | T18: 98 | U18: 24 | V18: 4 | W18: 0 | X18: 0 | Y18: 87 | Z18: 74 | AA18: 54 | AB18: 57 | AC18: 68 | AD18: 76 | AE18: 81 | AF18: 73 | AG18: 66 | AH18: 66 | AI18: 66 | AJ18: 62 | AK18: 73 | AL18: 82 | AM18: 67 | AN18: 58 | AO18: 89 | AP18: 33 | AQ18: 0 | AR18: 0 | AS18: 3 | AT18: 96 | AU18: 62 | AV18: 92 | AW18: 72 | AX18: 70 | AY18: 74 | AZ18: 75 | BA18: 71 | BB18: 71 | BC18: 72 | BD18: 67 | BE18: 62 | BF18: 68 | BG18: 42 | BH18: 98 | BI18: 24 | BJ18: 4 | BK18: 0 | BL18: 4 | BM18: 9 | BN18: 82 | BO18: 104 | BP18: 109 | BQ18: 56 | BR18: 73 | BS18: 96 | BT18: 87 | BU18: 57 | BV18: 61 | BW18: 40 | BX18: 53 | BY18: 79 | BZ18: 88 | CA18: 102 | CB18: 49 | CC18: 61 | CD18: 104 | CE18: 3
D19: 0 | E19: 2 | F19: 90 | G19: 47 | H19: 63 | I19: 65 | J19: 70 | K19: 73 | L19: 76 | M19: 78 | N19: 74 | O19: 72 | P19: 69 | Q19: 63 | R19: 55 | S19: 61 | T19: 104 | U19: 14 | V19: 2 | W19: 0 | X19: 0 | Y19: 70 | Z19: 49 | AA19: 6 | AB19: 14 | AC19: 63 | AD19: 77 | AE19: 72 | AF19: 70 | AG19: 66 | AH19: 69 | AI19: 66 | AJ19: 65 | AK19: 53 | AL19: 29 | AM19: 27 | AN19: 33 | AO19: 74 | AP19: 19 | AQ19: 0 | AR19: 0 | AS19: 2 | AT19: 90 | AU19: 47 | AV19: 63 | AW19: 65 | AX19: 70 | AY19: 73 | AZ19: 76 | BA19: 78 | BB19: 74 | BC19: 72 | BD19: 69 | BE19: 63 | BF19: 55 | BG19: 61 | BH19: 104 | BI19: 14 | BJ19: 2 | BK19: 0 | BL19: 2 | BM19: 32 | BN19: 136 | BO19: 115 | BP19: 127 | BQ19: 52 | BR19: 44 | BS19: 78 | BT19: 70 | BU19: 36 | BV19: 24 | BW19: 6 | BX19: 53 | BY19: 88 | BZ19: 58 | CA19: 50 | CB19: 27 | CC19: 111 | CD19: 77 | CE19: 0
D20: 0 | E20: 0 | F20: 107 | G20: 80 | H20: 38 | I20: 63 | J20: 68 | K20: 73 | L20: 71 | M20: 65 | N20: 66 | O20: 73 | P20: 69 | Q20: 59 | R20: 43 | S20: 44 | T20: 101 | U20: 7 | V20: 2 | W20: 0 | X20: 0 | Y20: 70 | Z20: 56 | AA20: 8 | AB20: 41 | AC20: 57 | AD20: 68 | AE20: 73 | AF20: 69 | AG20: 70 | AH20: 67 | AI20: 68 | AJ20: 57 | AK20: 47 | AL20: 35 | AM20: 14 | AN20: 34 | AO20: 48 | AP20: 11 | AQ20: 0 | AR20: 0 | AS20: 0 | AT20: 107 | AU20: 80 | AV20: 38 | AW20: 63 | AX20: 68 | AY20: 73 | AZ20: 71 | BA20: 65 | BB20: 66 | BC20: 73 | BD20: 69 | BE20: 59 | BF20: 43 | BG20: 44 | BH20: 101 | BI20: 7 | BJ20: 2 | BK20: 0 | BL20: 0 | BM20: 68 | BN20: 180 | BO20: 112 | BP20: 130 | BQ20: 63 | BR20: 45 | BS20: 86 | BT20: 91 | BU20: 101 | BV20: 46 | BW20: 10 | BX20: 16 | BY20: 22 | BZ20: 26 | CA20: 37 | CB20: 68 | CC20: 128 | CD20: 51 | CE20: 1
D21: 0 | E21: 0 | F21: 75 | G21: 115 | H21: 41 | I21: 55 | J21: 63 | K21: 63 | L21: 49 | M21: 39 | N21: 41 | O21: 62 | P21: 63 | Q21: 55 | R21: 42 | S21: 65 | T21: 87 | U21: 0 | V21: 3 | W21: 0 | X21: 0 | Y21: 45 | Z21: 68 | AA21: 8 | AB21: 43 | AC21: 77 | AD21: 82 | AE21: 63 | AF21: 64 | AG21: 64 | AH21: 53 | AI21: 62 | AJ21: 78 | AK21: 57 | AL21: 16 | AM21: 13 | AN21: 64 | AO21: 28 | AP21: 7 | AQ21: 0 | AR21: 0 | AS21: 0 | AT21: 75 | AU21: 115 | AV21: 41 | AW21: 55 | AX21: 63 | AY21: 63 | AZ21: 49 | BA21: 39 | BB21: 41 | BC21: 62 | BD21: 63 | BE21: 55 | BF21: 42 | BG21: 65 | BH21: 87 | BI21: 0 | BJ21: 3 | BK21: 0 | BL21: 2 | BM21: 39 | BN21: 126 | BO21: 73 | BP21: 73 | BQ21: 62 | BR21: 47 | BS21: 71 | BT21: 79 | BU21: 104 | BV21: 83 | BW21: 19 | BX21: 9 | BY21: 7 | BZ21: 37 | CA21: 55 | CB21: 90 | CC21: 91 | CD21: 32 | CE21: 2
... D28: 2 | E28: 3 | F28: 3 | G28: 16 | H28: 36 | I28: 35 | J28: 38 | K28: 44 | L28: 39 | M28: 40 | N28: 42 | O28: 29 | P28: 26 | Q28: 19 | R28: 5 | S28: 3 | T28: 2 | U28: 2 | V28: 2 | W28: 2 | X28: 5 | Y28: 5 | Z28: 23 | AA28: 45 | AB28: 37 | AC28: 52 | AD28: 36 | AE28: 46 | AF28: 30 | AG28: 22 | AH28: 41 | AI28: 54 | AJ28: 27 | AK28: 34 | AL28: 40 | AM28: 29 | AN28: 6 | AO28: 4 | AP28: 3 | AQ28: 3 | AR28: 2 | AS28: 3 | AT28: 3 | AU28: 16 | AV28: 36 | AW28: 35 | AX28: 38 | AY28: 44 | AZ28: 39 | BA28: 40 | BB28: 42 | BC28: 29 | BD28: 26 | BE28: 19 | BF28: 5 | BG28: 3 | BH28: 2 | BI28: 2 | BJ28: 2 | BK28: 2 | BL28: 2 | BM28: 2 | BN28: 4 | BO28: 4 | BP28: 5 | BQ28: 4 | BR28: 4 | BS28: 4 | BT28: 5 | BU28: 9 | BV28: 10 | BW28: 7 | BX28: 3 | BY28: 3 | BZ28: 2 | CA28: 2 | CB28: 3 | CC28: 3 | CD28: 3 | CE28: 3
C29: Class 2 | D29: 0 | E29: 0 | F29: 0 | G29: 1 | H29: 1 | I29: 0 | J29: 1 | K29: 1 | L29: 1 | M29: 1 | N29: 1 | O29: 1 | P29: 1 | Q29: 0 | R29: 0 | S29: 0 | T29: 0 | U29: 0 | V29: 0 | W29: 0 | X29: 0 | Y29: 0 | Z29: 0 | AA29: 0 | AB29: 1 | AC29: 1 | AD29: 1 | AE29: 1 | AF29: 1 | AG29: 1 | AH29: 1 | AI29: 1 | AJ29: 1 | AK29: 1 | AL29: 1 | AM29: 1 | AN29: 0 | AO29: 0 | AP29: 0 | AQ29: 0 | AR29: 0 | AS29: 0 | AT29: 1 | AU29: 1 | AV29: 1 | AW29: 1 | AX29: 1 | AY29: 1 | AZ29: 1 | BA29: 1 | BB29: 1 | BC29: 1 | BD29: 1 | BE29: 1 | BF29: 1 | BG29: 1 | BH29: 1 | BI29: 1 | BJ29: 0 | BK29: 0 | BL29: 0 | BM29: 0 | BN29: 0 | BO29: 0 | BP29: 0 | BQ29: 0 | BR29: 0 | BS29: 0 | BT29: 0 | BU29: 0 | BV29: 0 | BW29: 0 | BX29: 0 | BY29: 0 | BZ29: 0 | CA29: 0 | CB29: 0 | CC29: 0 | CD29: 0 | CE29: 0
C30: Meningioma | D30: 0 | E30: 2 | F30: 2 | G30: 2 | H30: 2 | I30: 3 | J30: 3 | K30: 3 | L30: 3 | M30: 2 | N30: 3 | O30: 3 | P30: 3 | Q30: 2 | R30: 2 | S30: 2 | T30: 2 | U30: 2 | V30: 1 | W30: 0 | X30: 0 | Y30: 3 | Z30: 4 | AA30: 4 | AB30: 4 | AC30: 4 | AD30: 4 | AE30: 4 | AF30: 4 | AG30: 4 | AH30: 4 | AI30: 3 | AJ30: 3 | AK30: 3 | AL30: 4 | AM30: 3 | AN30: 4 | AO30: 4 | AP30: 3 | AQ30: 0 | AR30: 0 | AS30: 3 | AT30: 4 | AU30: 4 | AV30: 4 | AW30: 4 | AX30: 4 | AY30: 4 | AZ30: 4 | BA30: 4 | BB30: 4 | BC30: 4 | BD30: 4 | BE30: 4 | BF30: 4 | BG30: 4 | BH30: 4 | BI30: 4 | BJ30: 3 | BK30: 0 | BL30: 0 | BM30: 1 | BN30: 2 | BO30: 2 | BP30: 2 | BQ30: 2 | BR30: 2 | BS30: 2 | BT30: 2 | BU30: 2 | BV30: 2 | BW30: 2 | BX30: 2 | BY30: 2 | BZ30: 2 | CA30: 2 | CB30: 2 | CC30: 2 | CD30: 2 | CE30: 0
D31: 0 | E31: 2 | F31: 2 | G31: 2 | H31: 2 | I31: 3 | J31: 3 | K31: 2 | L31: 4 | M31: 13 | N31: 1 | O31: 3 | P31: 2 | Q31: 3 | R31: 3 | S31: 2 | T31: 3 | U31: 3 | V31: 2 | W31: 0 | X31: 0 | Y31: 3 | Z31: 4 | AA31: 4 | AB31: 3 | AC31: 4 | AD31: 4 | AE31: 4 | AF31: 4 | AG31: 4 | AH31: 4 | AI31: 4 | AJ31: 4 | AK31: 3 | AL31: 4 | AM31: 3 | AN31: 4 | AO31: 4 | AP31: 3 | AQ31: 0 | AR31: 0 | AS31: 3 | AT31: 4 | AU31: 4 | AV31: 4 | AW31: 4 | AX31: 4 | AY31: 4 | AZ31: 4 | BA31: 3 | BB31: 4 | BC31: 3 | BD31: 3 | BE31: 4 | BF31: 4 | BG31: 4 | BH31: 4 | BI31: 4 | BJ31: 4 | BK31: 0 | BL31: 0 | BM31: 2 | BN31: 2 | BO31: 2 | BP31: 2 | BQ31: 2 | BR31: 2 | BS31: 2 | BT31: 2 | BU31: 0 | BV31: 0 | BW31: 1 | BX31: 2 | BY31: 2 | BZ31: 2 | CA31: 2 | CB31: 2 | CC31: 2 | CD31: 2 | CE31: 0
D32: 0 | E32: 2 | F32: 2 | G32: 2 | H32: 2 | I32: 0 | J32: 2 | K32: 2 | L32: 45 | M32: 74 | N32: 30 | O32: 4 | P32: 7 | Q32: 1 | R32: 1 | S32: 3 | T32: 2 | U32: 2 | V32: 2 | W32: 0 | X32: 0 | Y32: 3 | Z32: 4 | AA32: 4 | AB32: 4 | AC32: 4 | AD32: 4 | AE32: 5 | AF32: 5 | AG32: 4 | AH32: 4 | AI32: 5 | AJ32: 4 | AK32: 4 | AL32: 4 | AM32: 3 | AN32: 4 | AO32: 4 | AP32: 4 | AQ32: 0 | AR32: 0 | AS32: 4 | AT32: 4 | AU32: 4 | AV32: 3 | AW32: 3 | AX32: 3 | AY32: 4 | AZ32: 5 | BA32: 5 | BB32: 4 | BC32: 4 | BD32: 3 | BE32: 3 | BF32: 3 | BG32: 4 | BH32: 4 | BI32: 4 | BJ32: 4 | BK32: 1 | BL32: 0 | BM32: 2 | BN32: 2 | BO32: 2 | BP32: 3 | BQ32: 3 | BR32: 0 | BS32: 0 | BT32: 10 | BU32: 29 | BV32: 33 | BW32: 17 | BX32: 0 | BY32: 0 | BZ32: 3 | CA32: 2 | CB32: 2 | CC32: 2 | CD32: 2 | CE32: 0
D33: 1 | E33: 3 | F33: 3 | G33: 0 | H33: 9 | I33: 32 | J33: 37 | K33: 54 | L33: 72 | M33: 82 | N33: 67 | O33: 49 | P33: 42 | Q33: 47 | R33: 17 | S33: 0 | T33: 3 | U33: 3 | V33: 2 | W33: 0 | X33: 0 | Y33: 3 | Z33: 4 | AA33: 3 | AB33: 4 | AC33: 5 | AD33: 5 | AE33: 2 | AF33: 2 | AG33: 6 | AH33: 6 | AI33: 1 | AJ33: 1 | AK33: 4 | AL33: 4 | AM33: 3 | AN33: 3 | AO33: 4 | AP33: 4 | AQ33: 1 | AR33: 1 | AS33: 3 | AT33: 4 | AU33: 3 | AV33: 3 | AW33: 4 | AX33: 5 | AY33: 5 | AZ33: 4 | BA33: 3 | BB33: 3 | BC33: 4 | BD33: 5 | BE33: 4 | BF33: 3 | BG33: 3 | BH33: 4 | BI33: 4 | BJ33: 4 | BK33: 1 | BL33: 0 | BM33: 2 | BN33: 3 | BO33: 3 | BP33: 3 | BQ33: 0 | BR33: 24 | BS33: 85 | BT33: 116 | BU33: 118 | BV33: 122 | BW33: 125 | BX33: 95 | BY33: 27 | BZ33: 0 | CA33: 3 | CB33: 2 | CC33: 3 | CD33: 2 | CE33: 0
D34: 1 | E34: 3 | F34: 1 | G34: 26 | H34: 83 | I34: 85 | J34: 59 | K34: 101 | L34: 80 | M34: 86 | N34: 77 | O34: 88 | P34: 61 | Q34: 89 | R34: 78 | S34: 38 | T34: 0 | U34: 3 | V34: 3 | W34: 0 | X34: 1 | Y34: 3 | Z34: 4 | AA34: 4 | AB34: 5 | AC34: 5 | AD34: 4 | AE34: 44 | AF34: 105 | AG34: 130 | AH34: 132 | AI34: 108 | AJ34: 48 | AK34: 3 | AL34: 4 | AM34: 4 | AN34: 4 | AO34: 4 | AP34: 4 | AQ34: 1 | AR34: 1 | AS34: 4 | AT34: 3 | AU34: 3 | AV34: 3 | AW34: 5 | AX34: 5 | AY34: 3 | AZ34: 8 | BA34: 20 | BB34: 22 | BC34: 10 | BD34: 2 | BE34: 4 | BF34: 5 | BG34: 4 | BH34: 4 | BI34: 4 | BJ34: 4 | BK34: 1 | BL34: 0 | BM34: 2 | BN34: 3 | BO34: 3 | BP34: 0 | BQ34: 52 | BR34: 125 | BS34: 109 | BT34: 73 | BU34: 60 | BV34: 65 | BW34: 67 | BX34: 88 | BY34: 121 | BZ34: 56 | CA34: 0 | CB34: 2 | CC34: 3 | CD34: 2 | CE34: 0
D35: 1 | E35: 2 | F35: 6 | G35: 90 | H35: 86 | I35: 88 | J35: 100 | K35: 82 | L35: 59 | M35: 80 | N35: 55 | O35: 81 | P35: 99 | Q35: 65 | R35: 75 | S35: 103 | T35: 27 | U35: 1 | V35: 3 | W35: 0 | X35: 1 | Y35: 4 | Z35: 4 | AA35: 5 | AB35: 5 | AC35: 4 | AD35: 71 | AE35: 144 | AF35: 115 | AG35: 98 | AH35: 102 | AI35: 129 | AJ35: 155 | AK35: 79 | AL35: 1 | AM35: 5 | AN35: 4 | AO35: 4 | AP35: 4 | AQ35: 1 | AR35: 1 | AS35: 4 | AT35: 4 | AU35: 4 | AV35: 4 | AW35: 5 | AX35: 4 | AY35: 43 | AZ35: 109 | BA35: 142 | BB35: 151 | BC35: 131 | BD35: 60 | BE35: 6 | BF35: 5 | BG35: 5 | BH35: 4 | BI35: 4 | BJ35: 4 | BK35: 1 | BL35: 0 | BM35: 3 | BN35: 3 | BO35: 0 | BP35: 44 | BQ35: 109 | BR35: 78 | BS35: 66 | BT35: 67 | BU35: 74 | BV35: 72 | BW35: 68 | BX35: 55 | BY35: 70 | BZ35: 107 | CA35: 59 | CB35: 1 | CC35: 3 | CD35: 3 | CE35: 0
D36: 1 | E36: 0 | F36: 34 | G36: 100 | H36: 70 | I36: 61 | J36: 84 | K36: 27 | L36: 40 | M36: 65 | N36: 48 | O36: 55 | P36: 94 | Q36: 56 | R36: 70 | S36: 110 | T36: 71 | U36: 0 | V36: 3 | W36: 1 | X36: 1 | Y36: 4 | Z36: 5 | AA36: 5 | AB36: 2 | AC36: 44 | AD36: 137 | AE36: 76 | AF36: 63 | AG36: 85 | AH36: 95 | AI36: 63 | AJ36: 79 | AK36: 153 | AL36: 57 | AM36: 1 | AN36: 5 | AO36: 4 | AP36: 4 | AQ36: 1 | AR36: 1 | AS36: 4 | AT36: 4 | AU36: 4 | AV36: 5 | AW36: 3 | AX36: 44 | AY36: 131 | AZ36: 125 | BA36: 95 | BB36: 92 | BC36: 132 | BD36: 160 | BE36: 71 | BF36: 2 | BG36: 5 | BH36: 4 | BI36: 4 | BJ36: 4 | BK36: 1 | BL36: 1 | BM36: 3 | BN36: 2 | BO36: 14 | BP36: 105 | BQ36: 79 | BR36: 71 | BS36: 77 | BT36: 84 | BU36: 78 | BV36: 74 | BW36: 70 | BX36: 83 | BY36: 98 | BZ36: 70 | CA36: 83 | CB36: 34 | CC36: 0 | CD36: 3 | CE36: 1
D37: 1 | E37: 0 | F37: 63 | G37: 96 | H37: 64 | I37: 73 | J37: 99 | K37: 91 | L37: 56 | M37: 61 | N37: 51 | O37: 88 | P37: 89 | Q37: 77 | R37: 58 | S37: 106 | T37: 89 | U37: 3 | V37: 3 | W37: 1 | X37: 1 | Y37: 4 | Z37: 5 | AA37: 5 | AB37: 10 | AC37: 112 | AD37: 106 | AE37: 64 | AF37: 71 | AG37: 87 | AH37: 91 | AI37: 80 | AJ37: 72 | AK37: 103 | AL37: 147 | AM37: 18 | AN37: 3 | AO37: 5 | AP37: 4 | AQ37: 1 | AR37: 1 | AS37: 4 | AT37: 4 | AU37: 5 | AV37: 4 | AW37: 16 | AX37: 115 | AY37: 103 | AZ37: 64 | BA37: 86 | BB37: 82 | BC37: 68 | BD37: 104 | BE37: 162 | BF37: 41 | BG37: 1 | BH37: 5 | BI37: 4 | BJ37: 4 | BK37: 1 | BL37: 1 | BM37: 3 | BN37: 0 | BO37: 68 | BP37: 94 | BQ37: 66 | BR37: 77 | BS37: 86 | BT37: 86 | BU37: 72 | BV37: 77 | BW37: 103 | BX37: 105 | BY37: 96 | BZ37: 96 | CA37: 67 | CB37: 71 | CC37: 4 | CD37: 3 | CE37: 1
D38: 1 | E38: 1 | F38: 78 | G38: 95 | H38: 81 | I38: 85 | J38: 73 | K38: 41 | L38: 11 | M38: 22 | N38: 15 | O38: 53 | P38: 53 | Q38: 48 | R38: 68 | S38: 99 | T38: 98 | U38: 5 | V38: 3 | W38: 1 | X38: 1 | Y38: 5 | Z38: 5 | AA38: 2 | AB38: 55 | AC38: 134 | AD38: 71 | AE38: 79 | AF38: 128 | AG38: 172 | AH38: 120 | AI38: 82 | AJ38: 81 | AK38: 68 | AL38: 141 | AM38: 94 | AN38: 1 | AO38: 4 | AP38: 4 | AQ38: 1 | AR38: 1 | AS38: 4 | AT38: 5 | AU38: 5 | AV38: 2 | AW38: 66 | AX38: 127 | AY38: 73 | AZ38: 131 | BA38: 164 | BB38: 123 | BC38: 72 | BD38: 70 | BE38: 140 | BF38: 131 | BG38: 8 | BH38: 4 | BI38: 4 | BJ38: 4 | BK38: 2 | BL38: 1 | BM38: 2 | BN38: 11 | BO38: 107 | BP38: 72 | BQ38: 81 | BR38: 84 | BS38: 87 | BT38: 89 | BU38: 75 | BV38: 82 | BW38: 115 | BX38: 95 | BY38: 94 | BZ38: 97 | CA38: 73 | CB38: 87 | CC38: 27 | CD38: 1 | CE38: 1
D39: 1 | E39: 1 | F39: 87 | G39: 87 | H39: 65 | I39: 64 | J39: 56 | K39: 63 | L39: 54 | M39: 42 | N39: 77 | O39: 77 | P39: 61 | Q39: 48 | R39: 63 | S39: 82 | T39: 102 | U39: 6 | V39: 3 | W39: 1 | X39: 1 | Y39: 5 | Z39: 4 | AA39: 7 | AB39: 115 | AC39: 101 | AD39: 66 | AE39: 113 | AF39: 163 | AG39: 165 | AH39: 147 | AI39: 85 | AJ39: 93 | AK39: 79 | AL39: 87 | AM39: 158 | AN39: 31 | AO39: 2 | AP39: 4 | AQ39: 1 | AR39: 1 | AS39: 4 | AT39: 5 | AU39: 3 | AV39: 18 | AW39: 122 | AX39: 95 | AY39: 111 | AZ39: 152 | BA39: 156 | BB39: 130 | BC39: 77 | BD39: 78 | BE39: 82 | BF39: 171 | BG39: 63 | BH39: 1 | BI39: 4 | BJ39: 4 | BK39: 2 | BL39: 1 | BM39: 0 | BN39: 37 | BO39: 97 | BP39: 72 | BQ39: 81 | BR39: 89 | BS39: 91 | BT39: 85 | BU39: 76 | BV39: 86 | BW39: 114 | BX39: 92 | BY39: 92 | BZ39: 94 | CA39: 91 | CB39: 85 | CC39: 61 | CD39: 0 | CE39: 1
D40: 2 | E40: 3 | F40: 90 | G40: 78 | H40: 45 | I40: 50 | J40: 56 | K40: 86 | L40: 90 | M40: 71 | N40: 87 | O40: 83 | P40: 79 | Q40: 51 | R40: 40 | S40: 54 | T40: 104 | U40: 15 | V40: 3 | W40: 1 | X40: 1 | Y40: 5 | Z40: 2 | AA40: 31 | AB40: 141 | AC40: 79 | AD40: 73 | AE40: 140 | AF40: 161 | AG40: 161 | AH40: 141 | AI40: 87 | AJ40: 97 | AK40: 90 | AL40: 76 | AM40: 138 | AN40: 88 | AO40: 0 | AP40: 5 | AQ40: 2 | AR40: 1 | AS40: 4 | AT40: 5 | AU40: 2 | AV40: 55 | AW40: 138 | AX40: 81 | AY40: 156 | AZ40: 152 | BA40: 157 | BB40: 142 | BC40: 85 | BD40: 89 | BE40: 69 | BF40: 136 | BG40: 133 | BH40: 10 | BI40: 3 | BJ40: 4 | BK40: 2 | BL40: 1 | BM40: 0 | BN40: 57 | BO40: 85 | BP40: 76 | BQ40: 93 | BR40: 94 | BS40: 84 | BT40: 62 | BU40: 82 | BV40: 80 | BW40: 115 | BX40: 109 | BY40: 101 | BZ40: 100 | CA40: 85 | CB40: 68 | CC40: 79 | CD40: 2 | CE40: 1
D41: 1 | E41: 2 | F41: 89 | G41: 87 | H41: 28 | I41: 17 | J41: 34 | K41: 83 | L41: 55 | M41: 59 | N41: 65 | O41: 50 | P41: 37 | Q41: 22 | R41: 9 | S41: 35 | T41: 89 | U41: 26 | V41: 1 | W41: 1 | X41: 1 | Y41: 5 | Z41: 0 | AA41: 56 | AB41: 144 | AC41: 81 | AD41: 80 | AE41: 111 | AF41: 189 | AG41: 181 | AH41: 127 | AI41: 92 | AJ41: 99 | AK41: 95 | AL41: 85 | AM41: 116 | AN41: 121 | AO41: 3 | AP41: 5 | AQ41: 2 | AR41: 1 | AS41: 4 | AT41: 5 | AU41: 3 | AV41: 92 | AW41: 130 | AX41: 75 | AY41: 149 | AZ41: 176 | BA41: 173 | BB41: 132 | BC41: 90 | BD41: 97 | BE41: 80 | BF41: 105 | BG41: 161 | BH41: 30 | BI41: 1 | BJ41: 4 | BK41: 2 | BL41: 1 | BM41: 0 | BN41: 58 | BO41: 87 | BP41: 70 | BQ41: 86 | BR41: 97 | BS41: 68 | BT41: 44 | BU41: 85 | BV41: 76 | BW41: 80 | BX41: 85 | BY41: 91 | BZ41: 81 | CA41: 67 | CB41: 64 | CC41: 85 | CD41: 4 | CE41: 1
D42: 1 | E42: 2 | F42: 67 | G42: 83 | H42: 22 | I42: 16 | J42: 62 | K42: 106 | L42: 106 | M42: 74 | N42: 66 | O42: 74 | P42: 67 | Q42: 38 | R42: 11 | S42: 14 | T42: 53 | U42: 24 | V42: 1 | W42: 1 | X42: 1 | Y42: 5 | Z42: 1 | AA42: 52 | AB42: 146 | AC42: 83 | AD42: 83 | AE42: 87 | AF42: 133 | AG42: 108 | AH42: 92 | AI42: 100 | AJ42: 97 | AK42: 96 | AL42: 87 | AM42: 116 | AN42: 131 | AO42: 4 | AP42: 4 | AQ42: 2 | AR42: 1 | AS42: 4 | AT42: 4 | AU42: 3 | AV42: 97 | AW42: 139 | AX42: 77 | AY42: 85 | AZ42: 125 | BA42: 107 | BB42: 86 | BC42: 94 | BD42: 93 | BE42: 92 | BF42: 108 | BG42: 162 | BH42: 36 | BI42: 1 | BJ42: 4 | BK42: 2 | BL42: 1 | BM42: 0 | BN42: 48 | BO42: 102 | BP42: 74 | BQ42: 87 | BR42: 96 | BS42: 49 | BT42: 52 | BU42: 89 | BV42: 79 | BW42: 84 | BX42: 80 | BY42: 78 | BZ42: 77 | CA42: 71 | CB42: 69 | CC42: 83 | CD42: 1 | CE42: 1
... D52: 0 | E52: 1 | F52: 1 | G52: 1 | H52: 1 | I52: 2 | J52: 1 | K52: 2 | L52: 2 | M52: 1 | N52: 1 | O52: 1 | P52: 1 | Q52: 1 | R52: 1 | S52: 1 | T52: 1 | U52: 1 | V52: 1 | W52: 0 | X52: 0 | Y52: 1 | Z52: 1 | AA52: 1 | AB52: 2 | AC52: 2 | AD52: 2 | AE52: 2 | AF52: 2 | AG52: 2 | AH52: 2 | AI52: 2 | AJ52: 2 | AK52: 2 | AL52: 2 | AM52: 2 | AN52: 2 | AO52: 1 | AP52: 1 | AQ52: 0 | AR52: 0 | AS52: 1 | AT52: 1 | AU52: 2 | AV52: 2 | AW52: 2 | AX52: 2 | AY52: 2 | AZ52: 2 | BA52: 2 | BB52: 2 | BC52: 2 | BD52: 2 | BE52: 2 | BF52: 2 | BG52: 2 | BH52: 2 | BI52: 2 | BJ52: 1 | BK52: 0 | BL52: 0 | BM52: 1 | BN52: 1 | BO52: 1 | BP52: 1 | BQ52: 1 | BR52: 1 | BS52: 1 | BT52: 1 | BU52: 1 | BV52: 1 | BW52: 1 | BX52: 1 | BY52: 1 | BZ52: 1 | CA52: 1 | CB52: 1 | CC52: 1 | CD52: 1 | CE52: 0
C53: Class 3 | D53: 0 | E53: 1 | F53: 1 | G53: 1 | H53: 1 | I53: 1 | J53: 1 | K53: 1 | L53: 2 | M53: 1 | N53: 1 | O53: 2 | P53: 2 | Q53: 2 | R53: 2 | S53: 1 | T53: 1 | U53: 1 | V53: 1 | W53: 0 | X53: 1 | Y53: 1 | Z53: 1 | AA53: 1 | AB53: 1 | AC53: 1 | AD53: 1 | AE53: 1 | AF53: 1 | AG53: 1 | AH53: 1 | AI53: 1 | AJ53: 1 | AK53: 1 | AL53: 1 | AM53: 1 | AN53: 1 | AO53: 1 | AP53: 1 | AQ53: 1 | AR53: 15 | AS53: 15 | AT53: 16 | AU53: 16 | AV53: 16 | AW53: 16 | AX53: 16 | AY53: 16 | AZ53: 17 | BA53: 16 | BB53: 16 | BC53: 16 | BD53: 16 | BE53: 17 | BF53: 17 | BG53: 16 | BH53: 16 | BI53: 16 | BJ53: 16 | BK53: 16 | BL53: 0 | BM53: 0 | BN53: 0 | BO53: 0 | BP53: 0 | BQ53: 0 | BR53: 0 | BS53: 4 | BT53: 11 | BU53: 18 | BV53: 16 | BW53: 12 | BX53: 7 | BY53: 2 | BZ53: 0 | CA53: 0 | CB53: 0 | CC53: 0 | CD53: 0 | CE53: 0
C54: No tumor | D54: 0 | E54: 2 | F54: 3 | G54: 3 | H54: 3 | I54: 3 | J54: 3 | K54: 1 | L54: 0 | M54: 0 | N54: 0 | O54: 0 | P54: 1 | Q54: 3 | R54: 3 | S54: 3 | T54: 2 | U54: 3 | V54: 2 | W54: 0 | X54: 1 | Y54: 1 | Z54: 1 | AA54: 1 | AB54: 1 | AC54: 1 | AD54: 1 | AE54: 1 | AF54: 1 | AG54: 1 | AH54: 1 | AI54: 1 | AJ54: 1 | AK54: 1 | AL54: 1 | AM54: 1 | AN54: 1 | AO54: 1 | AP54: 1 | AQ54: 1 | AR54: 15 | AS54: 15 | AT54: 16 | AU54: 17 | AV54: 17 | AW54: 16 | AX54: 16 | AY54: 15 | AZ54: 15 | BA54: 15 | BB54: 15 | BC54: 15 | BD54: 16 | BE54: 17 | BF54: 17 | BG54: 16 | BH54: 16 | BI54: 16 | BJ54: 16 | BK54: 16 | BL54: 0 | BM54: 0 | BN54: 0 | BO54: 0 | BP54: 0 | BQ54: 14 | BR54: 32 | BS54: 48 | BT54: 49 | BU54: 26 | BV54: 27 | BW54: 39 | BX54: 52 | BY54: 48 | BZ54: 35 | CA54: 20 | CB54: 1 | CC54: 0 | CD54: 0 | CE54: 0
D55: 0 | E55: 2 | F55: 3 | G55: 3 | H55: 3 | I55: 2 | J55: 0 | K55: 17 | L55: 33 | M55: 31 | N55: 38 | O55: 31 | P55: 10 | Q55: 0 | R55: 2 | S55: 3 | T55: 3 | U55: 3 | V55: 1 | W55: 0 | X55: 1 | Y55: 1 | Z55: 1 | AA55: 1 | AB55: 1 | AC55: 1 | AD55: 0 | AE55: 0 | AF55: 0 | AG55: 3 | AH55: 4 | AI55: 2 | AJ55: 0 | AK55: 0 | AL55: 1 | AM55: 1 | AN55: 1 | AO55: 1 | AP55: 1 | AQ55: 1 | AR55: 16 | AS55: 16 | AT55: 16 | AU55: 16 | AV55: 16 | AW55: 15 | AX55: 17 | AY55: 22 | AZ55: 29 | BA55: 30 | BB55: 31 | BC55: 31 | BD55: 28 | BE55: 23 | BF55: 18 | BG55: 16 | BH55: 16 | BI55: 16 | BJ55: 16 | BK55: 16 | BL55: 0 | BM55: 0 | BN55: 0 | BO55: 7 | BP55: 31 | BQ55: 67 | BR55: 110 | BS55: 121 | BT55: 134 | BU55: 120 | BV55: 93 | BW55: 42 | BX55: 95 | BY55: 129 | BZ55: 115 | CA55: 54 | CB55: 34 | CC55: 13 | CD55: 0 | CE55: 0
D56: 0 | E56: 3 | F56: 3 | G56: 4 | H56: 2 | I56: 12 | J56: 63 | K56: 99 | L56: 96 | M56: 109 | N56: 103 | O56: 116 | P56: 109 | Q56: 56 | R56: 6 | S56: 3 | T56: 3 | U56: 4 | V56: 2 | W56: 0 | X56: 1 | Y56: 1 | Z56: 1 | AA56: 1 | AB56: 1 | AC56: 0 | AD56: 8 | AE56: 35 | AF56: 50 | AG56: 53 | AH56: 54 | AI56: 65 | AJ56: 62 | AK56: 11 | AL56: 0 | AM56: 1 | AN56: 1 | AO56: 1 | AP56: 1 | AQ56: 1 | AR56: 16 | AS56: 17 | AT56: 17 | AU56: 17 | AV56: 15 | AW56: 21 | AX56: 33 | AY56: 42 | AZ56: 40 | BA56: 42 | BB56: 30 | BC56: 33 | BD56: 31 | BE56: 28 | BF56: 33 | BG56: 24 | BH56: 16 | BI56: 17 | BJ56: 16 | BK56: 16 | BL56: 0 | BM56: 0 | BN56: 5 | BO56: 42 | BP56: 69 | BQ56: 134 | BR56: 140 | BS56: 170 | BT56: 141 | BU56: 95 | BV56: 117 | BW56: 132 | BX56: 125 | BY56: 112 | BZ56: 139 | CA56: 140 | CB56: 70 | CC56: 47 | CD56: 20 | CE56: 0
D57: 0 | E57: 2 | F57: 3 | G57: 2 | H57: 16 | I57: 76 | J57: 75 | K57: 55 | L57: 55 | M57: 48 | N57: 57 | O57: 61 | P57: 59 | Q57: 100 | R57: 66 | S57: 3 | T57: 3 | U57: 3 | V57: 2 | W57: 0 | X57: 1 | Y57: 1 | Z57: 1 | AA57: 1 | AB57: 0 | AC57: 22 | AD57: 61 | AE57: 54 | AF57: 73 | AG57: 105 | AH57: 29 | AI57: 30 | AJ57: 62 | AK57: 91 | AL57: 34 | AM57: 0 | AN57: 1 | AO57: 1 | AP57: 1 | AQ57: 1 | AR57: 18 | AS57: 17 | AT57: 17 | AU57: 16 | AV57: 29 | AW57: 36 | AX57: 61 | AY57: 93 | AZ57: 89 | BA57: 91 | BB57: 73 | BC57: 88 | BD57: 86 | BE57: 69 | BF57: 39 | BG57: 39 | BH57: 29 | BI57: 16 | BJ57: 17 | BK57: 17 | BL57: 0 | BM57: 0 | BN57: 47 | BO57: 56 | BP57: 122 | BQ57: 99 | BR57: 81 | BS57: 92 | BT57: 87 | BU57: 102 | BV57: 136 | BW57: 153 | BX57: 111 | BY57: 97 | BZ57: 135 | CA57: 150 | CB57: 117 | CC57: 84 | CD57: 50 | CE57: 15
...

Sheet Perceptron
B2: P | C2: E | D2: R | E2: C | F2: E | G2: P | H2: T | I2: R | J2: O | K2: N | M2: Core of a Neural Net
G4: 1 | H4: 2 | I4: 3 | J4: 4 | K4: 5 | L4: 6 | M4: 7 | N4: 8 | O4: 9 | P4: 10 | Q4: 11 | R4: 12 | S4: 13 | T4: 14 | U4: 15 | V4: 16 | W4: 17 | X4: 18 | Y4: 19 | Z4: 20
F5: 1 | G5: {=OFFSET('Dataset-Tumor'!D5, 24*(E6-1), 20*(E7-1), 24, 20)} -> 0 | H5: 0 | I5: 0 | J5: 0 | K5: 1 | L5: 1 | M5: 1 | N5: 1 | O5: 1 | P5: 1 | Q5: 1 | R5: 1 | S5: 1 | T5: 1 | U5: 1 | V5: 1 | W5: 0 | X5: 0 | Y5: 0 | Z5: 0 | AH5: X | AM5: X: Normalized
D6: Class # | E6: 2 | F6: 2 | G6: 0 | H6: 3 | I6: 4 | J6: 4 | K6: 4 | L6: 4 | M6: 4 | N6: 4 | O6: 4 | P6: 4 | Q6: 4 | R6: 3 | S6: 3 | T6: 3 | U6: 4 | V6: 3 | W6: 4 | X6: 4 | Y6: 3 | Z6: 0 | AH6: {=N15:P17} -> 113 | AI6: 163 | AJ6: 165 | AM6: {=ROUND((_xlfn.ANCHORARRAY(AH6)-127.5)/127.5,1)} -> -0.1 | AN6: 0.3 | AO6: 0.3
D7: Sample # | E7: 2 | F7: 3 | G7: 0 | H7: 3 | I7: 4 | J7: 4 | K7: 3 | L7: 4 | M7: 4 | N7: 4 | O7: 4 | P7: 4 | Q7: 4 | R7: 4 | S7: 4 | T7: 3 | U7: 4 | V7: 3 | W7: 4 | X7: 4 | Y7: 3 | Z7: 0 | AH7: 140 | AI7: 161 | AJ7: 161 | AM7: 0.1 | AN7: 0.3 | AO7: 0.3
F8: 4 | G8: 0 | H8: 3 | I8: 4 | J8: 4 | K8: 4 | L8: 4 | M8: 4 | N8: 5 | O8: 5 | P8: 4 | Q8: 4 | R8: 5 | S8: 4 | T8: 4 | U8: 4 | V8: 3 | W8: 4 | X8: 4 | Y8: 4 | Z8: 0 | AH8: 111 | AI8: 189 | AJ8: 181 | AM8: -0.1 | AN8: 0.5 | AO8: 0.4 | AS8: X | AU8: W | AX8: b | BF8: X
E9: ȳ=OHE | F9: 5 | G9: 0 | H9: 3 | I9: 4 | J9: 3 | K9: 4 | L9: 5 | M9: 5 | N9: 2 | O9: 2 | P9: 6 | Q9: 6 | R9: 1 | S9: 1 | T9: 4 | U9: 4 | V9: 3 | W9: 3 | X9: 4 | Y9: 4 | Z9: 1 | AS9: {=_xlfn.ANCHORARRAY(AN12)} -> -0.1 | AU9: {=TRANSPOSE(AC25:AK25)} -> 1 | AX9: =AL25 -> 1 | BF9: {=_xlfn.ANCHORARRAY(AN12)} -> -0.1
D10: Glioma | E10: {=TRANSPOSE(IF(_xlfn.SEQUENCE(1,COUNT([0]!Classes),1,1)=E6,1,0))} -> 0 | F10: 6 | G10: 1 | H10: 3 | I10: 4 | J10: 4 | K10: 5 | L10: 5 | M10: 4 | N10: 44 | O10: 105 | P10: 130 | Q10: 132 | R10: 108 | S10: 48 | T10: 3 | U10: 4 | V10: 4 | W10: 4 | X10: 4 | Y10: 4 | Z10: 1 | AN10: Feature Vector | AS10: 0.3 | AU10: 1 | BF10: 0.3
D11: Meningioma | E11: 1 | F11: 7 | G11: 1 | H11: 4 | I11: 4 | J11: 5 | K11: 5 | L11: 4 | M11: 71 | N11: 144 | O11: 115 | P11: 98 | Q11: 102 | R11: 129 | S11: 155 | T11: 79 | U11: 1 | V11: 5 | W11: 4 | X11: 4 | Y11: 4 | Z11: 1 | AN11: X: Flatten | AS11: 0.3 | AU11: 0 | BF11: 0.3 | BM11: y
D12: No tumor | E12: 0 | F12: 8 | G12: 1 | H12: 4 | I12: 5 | J12: 5 | K12: 2 | L12: 44 | M12: 137 | N12: 76 | O12: 63 | P12: 85 | Q12: 95 | R12: 63 | S12: 79 | T12: 153 | U12: 57 | V12: 1 | W12: 5 | X12: 4 | Y12: 4 | Z12: 1 | AN12: {=_xlfn.TOCOL(_xlfn.ANCHORARRAY(AM6))} -> -0.1 | AS12: 0.1 | AU12: 0 | BF12: 0.1 | BK12: {=_xlfn.ANCHORARRAY(AN24)} -> 1.9 | BM12: {=_xlfn.ANCHORARRAY(AT24)} -> 0.29
D13: Pituitary | E13: 0 | F13: 9 | G13: 1 | H13: 4 | I13: 5 | J13: 5 | K13: 10 | L13: 112 | M13: 106 | N13: 64 | O13: 71 | P13: 87 | Q13: 91 | R13: 80 | S13: 72 | T13: 103 | U13: 147 | V13: 18 | W13: 3 | X13: 5 | Y13: 4 | Z13: 1 | AN13: 0.3 | AS13: 0.3 | AU13: 0 | AX13: ∑ | AZ13: 𝜎 | BB13: y₂ | BF13: 0.3 | BK13: 1.5 | BM13: 0.19
F14: 10 | G14: 1 | H14: 5 | I14: 5 | J14: 2 | K14: 55 | L14: 134 | M14: 71 | N14: 79 | O14: 128 | P14: 172 | Q14: 120 | R14: 82 | S14: 81 | T14: 68 | U14: 141 | V14: 94 | W14: 1 | X14: 4 | Y14: 4 | Z14: 1 | AN14: 0.3 | AS14: 0.3 | AU14: 0 | AX14: =AN25 -> 1.5 | AZ14: =AT25 -> 0.19 | BF14: 0.3 | BK14: 2.1 | BM14: 0.36
F15: 11 | G15: 1 | H15: 5 | I15: 4 | J15: 7 | K15: 115 | L15: 101 | M15: 66 | N15: 113 | O15: 163 | P15: 165 | Q15: 147 | R15: 85 | S15: 93 | T15: 79 | U15: 87 | V15: 158 | W15: 31 | X15: 2 | Y15: 4 | Z15: 1 | AN15: 0.1 | AS15: -0.1 | AU15: 1 | BF15: -0.1 | BK15: 1.3 | BM15: 0.16
F16: 12 | G16: 1 | H16: 5 | I16: 2 | J16: 31 | K16: 141 | L16: 79 | M16: 73 | N16: 140 | O16: 161 | P16: 161 | Q16: 141 | R16: 87 | S16: 97 | T16: 90 | U16: 76 | V16: 138 | W16: 88 | X16: 0 | Y16: 5 | Z16: 2 | AN16: 0.3 | AO16: dim=9 | AS16: 0.5 | AU16: 0 | BF16: 0.5
F17: 13 | G17: 1 | H17: 5 | I17: 0 | J17: 56 | K17: 144 | L17: 81 | M17: 80 | N17: 111 | O17: 189 | P17: 181 | Q17: 127 | R17: 92 | S17: 99 | T17: 95 | U17: 85 | V17: 116 | W17: 121 | X17: 3 | Y17: 5 | Z17: 2 | AN17: 0.3 | AS17: 0.4 | AU17: 1 | BF17: 0.4
F18: 14 | G18: 1 | H18: 5 | I18: 1 | J18: 52 | K18: 146 | L18: 83 | M18: 83 | N18: 87 | O18: 133 | P18: 108 | Q18: 92 | R18: 100 | S18: 97 | T18: 96 | U18: 87 | V18: 116 | W18: 131 | X18: 4 | Y18: 4 | Z18: 2 | AN18: -0.1
F19: 15 | G19: 1 | H19: 5 | I19: 3 | J19: 20 | K19: 145 | L19: 108 | M19: 85 | N19: 86 | O19: 88 | P19: 88 | Q19: 94 | R19: 98 | S19: 98 | T19: 88 | U19: 76 | V19: 140 | W19: 103 | X19: 1 | Y19: 4 | Z19: 1 | AN19: 0.5
F20: 16 | G20: 1 | H20: 4 | I20: 5 | J20: 1 | K20: 88 | L20: 154 | M20: 77 | N20: 87 | O20: 93 | P20: 96 | Q20: 100 | R20: 93 | S20: 95 | T20: 77 | U20: 85 | V20: 173 | W20: 52 | X20: 0 | Y20: 4 | Z20: 1 | AN20: 0.4
F21: 17 | G21: 1 | H21: 4 | I21: 4 | J21: 3 | K21: 15 | L21: 139 | M21: 125 | N21: 73 | O21: 87 | P21: 94 | Q21: 93 | R21: 87 | S21: 81 | T21: 72 | U21: 159 | V21: 136 | W21: 8 | X21: 3 | Y21: 5 | Z21: 1 | AN21: 1
